Workbook

Sheet Resumen
A1: ESTADIO YAXCHÉ + PLAZA SAKBÉ — ¿Cuánto genera y cuándo se paga?
A2: Modelo financiero de concepto. Millones de pesos de 2026, sin inflación ni IVA. Tres escenarios: cambia cualquier número azul en "Supuestos" y todo se recalcula.
A5: Lo más importante | B5: Unidad | C5: Conservador | D5: Base | E5: Optimista
A6: Inversión de construcción (sin IVA, sin terreno) | B6: M MXN | C6: =Supuestos!$C$8 -> 53245 | D6: =Supuestos!$D$8 -> 53245 | E6: =Supuestos!$E$8 -> 53245
A7: Días de evento al año | B7: días | C7: =Eventos!$C$63 -> 42 | D7: =Eventos!$D$63 -> 58 | E7: =Eventos!$E$63 -> 77
A8: de ellos, conciertos | B8: conciertos | C8: =Eventos!$C$23 -> 8 | D8: =Eventos!$D$23 -> 12 | E8: =Eventos!$E$23 -> 18
A9: Asistentes a eventos al año | B9: personas | C9: =Eventos!$C$64 -> 2195000 | D9: =Eventos!$D$64 -> 3742000 | E9: =Eventos!$E$64 -> 5805000
A10: Ingresos del estadio | B10: M MXN/año | C10: =Ingresos!$C$66 -> 1147.8325 | D10: =Ingresos!$D$66 -> 2506.9224 | E10: =Ingresos!$E$66 -> 4829.6638
A11: Ingresos de la Plaza Sakbé | B11: M MXN/año | C11: =Ingresos!$C$67 -> 1340.6234 | D11: =Ingresos!$D$67 -> 1941.3497 | E11: =Ingresos!$E$67 -> 2640.9132
A12: Ingresos de energía y reciclaje | B12: M MXN/año | C12: =Ingresos!$C$65 -> 9.9101514 | D12: =Ingresos!$D$65 -> 18.165425 | E12: =Ingresos!$E$65 -> 28.928858
A13: INGRESOS TOTALES | B13: M MXN/año | C13: =Ingresos!$C$68 -> 2498.366 | D13: =Ingresos!$D$68 -> 4466.4375 | E13: =Ingresos!$E$68 -> 7499.5059
A14: Costos de operación | B14: M MXN/año | C14: =-Costos_Operacion!$C$42 -> -1881.5695 | D14: =-Costos_Operacion!$D$42 -> -1718.0966 | E14: =-Costos_Operacion!$E$42 -> -1627.9351
A15: EBITDA (lo que queda cada año) | B15: M MXN/año | C15: =Costos_Operacion!$C$46 -> 616.79651 | D15: =Costos_Operacion!$D$46 -> 2748.3409 | E15: =Costos_Operacion!$E$46 -> 5871.5708
A16: Margen | B16: % | C16: =Costos_Operacion!$C$47 -> 0.24687996 | D16: =Costos_Operacion!$D$47 -> 0.61533178 | E16: =Costos_Operacion!$E$47 -> 0.78292769
A17: Recuperación simple (inversión ÷ EBITDA) | B17: años | C17: =Supuestos!$C$8/Costos_Operacion!$C$46 -> 86.325067 | D17: =Supuestos!$D$8/Costos_Operacion!$D$46 -> 19.373506 | E17: =Supuestos!$E$8/Costos_Operacion!$E$46 -> 9.0682718
A18: Recuperación con flujo, después de impuestos | B18: años desde apertura | C18: =Flujo_30_anios!$B$22 -> más de 30 | D18: =Flujo_30_anios!$B$45 -> 20 | E18: =Flujo_30_anios!$B$68 -> 12
A19: TIR real antes de impuestos | B19: % | C19: =Flujo_30_anios!$B$20 -> -0.055436918 | D19: =Flujo_30_anios!$B$43 -> 0.026213253 | E19: =Flujo_30_anios!$B$66 -> 0.087628617
A20: TIR real después de impuestos | B20: % | C20: =Flujo_30_anios!$B$21 -> -0.063561192 | D20: =Flujo_30_anios!$B$44 -> 0.02013905 | E20: =Flujo_30_anios!$B$67 -> 0.069403752
A21: VPN a la tasa real (después de impuestos) | B21: M MXN | C21: =Flujo_30_anios!$B$19 -> -43123.864 | D21: =Flujo_30_anios!$B$42 -> -25058.117 | E21: =Flujo_30_anios!$B$65 -> -324.73558
A23: Energía | B23: Unidad | C23: Conservador | D23: Base | E23: Optimista
A24: Potencia solar instalada | B24: MWp | C24: =Energia!$C$16/1000 -> 12.58117 | D24: =Energia!$D$16/1000 -> 13.1109 | E24: =Energia!$E$16/1000 -> 13.64063
A25: Generación solar | B25: GWh/año | C25: =Energia!$C$20 -> 13.890757 | D25: =Energia!$D$20 -> 15.924749 | E25: =Energia!$E$20 -> 18.832145
A26: Energía solar que se pierde (calor, polvo, sombra, inversores, cables) | B26: GWh/año | C26: =Energia!$C$22 -> 5.1507079 | D26: =Energia!$D$22 -> 4.7737154 | E26: =Energia!$E$22 -> 4.1582029
A27: Consumo de todo el conjunto | B27: GWh/año | C27: =Energia!$C$31 -> 65.983664 | D27: =Energia!$D$31 -> 58.584957 | E27: =Energia!$E$31 -> 53.44767
A28: Estadio | B28: GWh/año | C28: =Energia!$C$27 -> 8.652 | D28: =Energia!$D$27 -> 8.594 | E28: =Energia!$E$27 -> 8.721
A29: Plaza Sakbé | B29: GWh/año | C29: =Energia!$C$28 -> 52.12134 | D29: =Energia!$D$28 -> 44.39966 | E29: =Energia!$E$28 -> 38.6084
A30: Estacionamiento y cargadores | B30: GWh/año | C30: =Energia!$C$29+Energia!$C$30 -> 5.210324 | D30: =Energia!$D$29+Energia!$D$30 -> 5.591297 | E30: =Energia!$E$29+Energia!$E$30 -> 6.11827
A31: Lo que cubren los paneles | B31: % | C31: =Energia!$C$34 -> 0.21051812 | D31: =Energia!$D$34 -> 0.27182318 | E31: =Energia!$E$34 -> 0.35234735
A32: La cubierta vs. lo que gasta el estadio | B32: % | C32: =Energia!$C$35 -> 1.2747673 | D32: =Energia!$D$35 -> 1.4718598 | E32: =Energia!$E$35 -> 1.7158242
A33: Energía que se compra a la red (todo el conjunto) | B33: GWh/año | C33: =Energia!$C$36 -> 52.092907 | D33: =Energia!$D$36 -> 42.660208 | E33: =Energia!$E$36 -> 34.615525
A34: Costo de esa energía (todo el conjunto) | B34: M MXN/año | C34: =Energia!$C$37 -> 161.48801 | D34: =Energia!$D$37 -> 119.44858 | E34: =Energia!$E$37 -> 86.538812
A35: de eso paga el dueño | B35: M MXN/año | C35: =Energia!$C$44 -> 56.463512 | D35: =Energia!$D$44 -> 38.6412 | E35: =Energia!$E$44 -> 23.800162
A36: y los locatarios en sus medidores | B36: M MXN/año | C36: =Energia!$C$45 -> 105.0245 | D36: =Energia!$D$45 -> 80.807381 | E36: =Energia!$E$45 -> 62.73865
A37: Ahorro por los paneles | B37: M MXN/año | C37: =Energia!$C$48 -> 43.061346 | D37: =Energia!$D$48 -> 44.589298 | E37: =Energia!$E$48 -> 47.080363
A38: Inversión solar (con indirectos) | B38: M MXN | C38: =Energia!$C$56 -> 819.80451 | D38: =Energia!$D$56 -> 823.84785 | E38: =Energia!$E$56 -> 827.89119
A39: Los paneles se pagan solos en (todo el sistema) | B39: años | C39: =Energia!$C$61 -> 19.488926 | D39: =Energia!$D$61 -> 17.875152 | E39: =Energia!$E$61 -> 15.956243
A40: solo los de la cubierta del estadio | B40: años | C40: =Energia!$C$57 -> 14.00178 | D40: =Energia!$D$57 -> 12.906556 | E40: =Energia!$E$57 -> 11.572945
A41: el vidrio solar de la fachada | B41: años | C41: =Energia!$C$59 -> 69.708548 | D41: =Energia!$D$59 -> 61.719309 | E41: =Energia!$E$59 -> 53.429503
A42: CO₂ evitado | B42: t/año | C42: =Energia!$C$51 -> 6084.1515 | D42: =Energia!$D$51 -> 6975.0402 | E42: =Energia!$E$51 -> 8248.4796
A43: Agua que no viene de la red (lluvia + reúso) | B43: % | C43: =Agua!$C$16 -> 0.4107736 | D43: =Agua!$D$16 -> 0.5304649 | E43: =Agua!$E$16 -> 0.65487656
...

Sheet Supuestos
A1: Supuestos del modelo (todo lo editable está aquí)
A2: Azul = dato editable. Negro = fórmula. Verde = liga a otra hoja. Pesos de 2026, sin inflación. Las tres columnas son tres escenarios: cambia cualquier número y todo el libro se recalcula.
A4: Concepto | B4: Unidad | C4: Conservador | D4: Base | E4: Optimista | F4: Nota / fuente
A6: Generales e inversión
A7: Tipo de cambio | B7: MXN/USD | C7: 18.5 | D7: 18.5 | E7: 18.5 | F7: Mismo supuesto que el presupuesto
A8: Inversión de construcción, sin IVA | B8: M MXN | C8: 53245 | D8: 53245 | E8: 53245 | F8: Presupuesto_Materiales_Yaxche_Sakbe.xlsx, total sin IVA (el IVA de obra se acredita). Sin terreno.
A9: Costo directo de obra | B9: M MXN | C9: 37235 | D9: 37235 | E9: 37235 | F9: Presupuesto: costo directo
A10: Parte del estadio (con indirectos) | B10: M MXN | C10: 17734 | D10: 17734 | E10: 17734 | F10: Presupuesto: indicadores
A11: Parte de la Plaza Sakbé (con indirectos) | B11: M MXN | C11: 17196 | D11: 17196 | E11: 17196 | F11: Presupuesto: indicadores
A12: Parte común: subterráneo, estacionamiento, explanada, redes | B12: M MXN | C12: 18316 | D12: 18316 | E12: 18316 | F12: Presupuesto: indicadores
A13: Gastos preoperativos y capital de trabajo | B13: M MXN | C13: 400 | D13: 300 | E13: 250 | F13: Contratación, marketing de apertura, pruebas, inventarios
A14: Avance de obra año 1 | B14: % | C14: 0.2 | D14: 0.2 | E14: 0.2 | F14: Obra de 4 años
A15: Avance de obra año 2 | B15: % | C15: 0.3 | D15: 0.3 | E15: 0.3
A16: Avance de obra año 3 | B16: % | C16: 0.3 | D16: 0.3 | E16: 0.3
A17: Avance de obra año 4 | B17: % | C17: 0.2 | D17: 0.2 | E17: 0.2
A18: Arranque: ingresos del año 1 de operación | B18: % del estable | C18: 0.8 | D18: 0.85 | E18: 0.9 | F18: Plaza a medio llenar y calendario de eventos incompleto
A19: Arranque: ingresos del año 2 de operación | B19: % del estable | C19: 0.9 | D19: 0.95 | E19: 1
A20: Tasa de descuento real | B20: % | C20: 0.09 | D20: 0.08 | E20: 0.07 | F20: Real (sin inflación). Equivale a ~12 % nominal con 4 % de inflación
A21: ISR | B21: % | C21: 0.3 | D21: 0.3 | E21: 0.3 | F21: Ley del ISR, personas morales
A22: Depreciación fiscal de construcciones | B22: %/año | C22: 0.05 | D22: 0.05 | E22: 0.05 | F22: LISR art. 34: 5 % anual (20 años)
A23: Esquema APP: fracción de la obra común que pone el gobierno | B23: % | C23: 1 | D23: 1 | E23: 1 | F23: Solo para el bloque "Base con APP" del flujo. Estacionamiento, explanada y redes son infraestructura pública
A25: Calendario de eventos del estadio
A26: Fútbol de liga (club local): eventos al año | B26: eventos | C26: 25 | D26: 30 | E26: 34
A27: Fútbol de liga (club local): asistencia promedio | B27: personas | C27: 45000 | D27: 58000 | E27: 70000
A28: Fútbol de liga (club local): boleto promedio | B28: MXN | C28: 380 | D28: 480 | E28: 600
A29: Fútbol de liga (club local): renta del estadio | B29: % de taquilla | C29: 0.1 | D29: 0.12 | E29: 0.15 | F29: Lo que el club / promotor paga al estadio
A30: Fútbol de liga (club local): gasto en alimentos y bebidas | B30: MXN/persona | C30: 150 | D30: 190 | E30: 240
A31: Selección nacional y partidos internacionales: eventos al año | B31: eventos | C31: 2 | D31: 3 | E31: 4
A32: Selección nacional y partidos internacionales: asistencia promedio | B32: personas | C32: 70000 | D32: 80000 | E32: 90000
A33: Selección nacional y partidos internacionales: boleto promedio | B33: MXN | C33: 700 | D33: 850 | E33: 1000
A34: Selección nacional y partidos internacionales: renta del estadio | B34: % de taquilla | C34: 0.12 | D34: 0.15 | E34: 0.18 | F34: Lo que el club / promotor paga al estadio
A35: Selección nacional y partidos internacionales: gasto en alimentos y bebidas | B35: MXN/persona | C35: 170 | D35: 210 | E35: 260
A36: Conciertos: eventos al año | B36: eventos | C36: 8 | D36: 12 | E36: 18 | F36: Un concierto al mes en el escenario base
A37: Conciertos: asistencia promedio | B37: personas | C37: 80000 | D37: 92000 | E37: 100000
A38: Conciertos: boleto promedio | B38: MXN | C38: 1700 | D38: 2200 | E38: 2600
A39: Conciertos: renta del estadio | B39: % de taquilla | C39: 0.08 | D39: 0.1 | E39: 0.12 | F39: Venue fee típico 8–12 % de la taquilla
A40: Conciertos: gasto en alimentos y bebidas | B40: MXN/persona | C40: 280 | D40: 350 | E40: 450
A41: NFL / fútbol americano: eventos al año | B41: eventos | C41: 0 | D41: 1 | E41: 1
A42: NFL / fútbol americano: asistencia promedio | B42: personas | C42: 70000 | D42: 78000 | E42: 85000
A43: NFL / fútbol americano: boleto promedio | B43: MXN | C43: 2500 | D43: 3200 | E43: 4000
...

Sheet Eventos
A1: Calendario de eventos del estadio
A2: Cuántos eventos, cuánta gente y cuánto se vende en taquilla. Dinero en millones de MXN.
A4: Concepto | B4: Unidad | C4: Conservador | D4: Base | E4: Optimista | F4: Nota / fuente
A6: Fútbol de liga (club local)
A7: Eventos al año | B7: eventos | C7: =Supuestos!$C$26 -> 25 | D7: =Supuestos!$D$26 -> 30 | E7: =Supuestos!$E$26 -> 34
A8: Asistencia por evento | B8: personas | C8: =MIN(Supuestos!$C$27,Supuestos!$C$61) -> 45000 | D8: =MIN(Supuestos!$D$27,Supuestos!$D$61) -> 58000 | E8: =MIN(Supuestos!$E$27,Supuestos!$E$61) -> 70000 | F8: Tope = aforo
A9: Asistentes al año | B9: personas | C9: =Eventos!$C$7*Eventos!$C$8 -> 1125000 | D9: =Eventos!$D$7*Eventos!$D$8 -> 1740000 | E9: =Eventos!$E$7*Eventos!$E$8 -> 2380000
A10: Taquilla bruta | B10: M MXN | C10: =Eventos!$C$9*Supuestos!$C$28/10^6 -> 427.5 | D10: =Eventos!$D$9*Supuestos!$D$28/10^6 -> 835.2 | E10: =Eventos!$E$9*Supuestos!$E$28/10^6 -> 1428 | F10: Va al club o al promotor
A11: Ventas de alimentos y bebidas | B11: M MXN | C11: =Eventos!$C$9*Supuestos!$C$30/10^6 -> 168.75 | D11: =Eventos!$D$9*Supuestos!$D$30/10^6 -> 330.6 | E11: =Eventos!$E$9*Supuestos!$E$30/10^6 -> 571.2
A12: Autos por evento | B12: autos | C12: =MIN(Supuestos!$C$123,Eventos!$C$8*Supuestos!$C$70) -> 3150 | D12: =MIN(Supuestos!$D$123,Eventos!$D$8*Supuestos!$D$70) -> 4640 | E12: =MIN(Supuestos!$E$123,Eventos!$E$8*Supuestos!$E$70) -> 5688
A14: Selección nacional y partidos internacionales
A15: Eventos al año | B15: eventos | C15: =Supuestos!$C$31 -> 2 | D15: =Supuestos!$D$31 -> 3 | E15: =Supuestos!$E$31 -> 4
A16: Asistencia por evento | B16: personas | C16: =MIN(Supuestos!$C$32,Supuestos!$C$61) -> 70000 | D16: =MIN(Supuestos!$D$32,Supuestos!$D$61) -> 80000 | E16: =MIN(Supuestos!$E$32,Supuestos!$E$61) -> 90000 | F16: Tope = aforo
A17: Asistentes al año | B17: personas | C17: =Eventos!$C$15*Eventos!$C$16 -> 140000 | D17: =Eventos!$D$15*Eventos!$D$16 -> 240000 | E17: =Eventos!$E$15*Eventos!$E$16 -> 360000
A18: Taquilla bruta | B18: M MXN | C18: =Eventos!$C$17*Supuestos!$C$33/10^6 -> 98 | D18: =Eventos!$D$17*Supuestos!$D$33/10^6 -> 204 | E18: =Eventos!$E$17*Supuestos!$E$33/10^6 -> 360 | F18: Va al club o al promotor
A19: Ventas de alimentos y bebidas | B19: M MXN | C19: =Eventos!$C$17*Supuestos!$C$35/10^6 -> 23.8 | D19: =Eventos!$D$17*Supuestos!$D$35/10^6 -> 50.4 | E19: =Eventos!$E$17*Supuestos!$E$35/10^6 -> 93.6
A20: Autos por evento | B20: autos | C20: =MIN(Supuestos!$C$123,Eventos!$C$16*Supuestos!$C$70) -> 4900 | D20: =MIN(Supuestos!$D$123,Eventos!$D$16*Supuestos!$D$70) -> 5688 | E20: =MIN(Supuestos!$E$123,Eventos!$E$16*Supuestos!$E$70) -> 5688
A22: Conciertos
A23: Eventos al año | B23: eventos | C23: =Supuestos!$C$36 -> 8 | D23: =Supuestos!$D$36 -> 12 | E23: =Supuestos!$E$36 -> 18
A24: Asistencia por evento | B24: personas | C24: =MIN(Supuestos!$C$37,Supuestos!$C$61) -> 80000 | D24: =MIN(Supuestos!$D$37,Supuestos!$D$61) -> 92000 | E24: =MIN(Supuestos!$E$37,Supuestos!$E$61) -> 100000 | F24: Tope = aforo
A25: Asistentes al año | B25: personas | C25: =Eventos!$C$23*Eventos!$C$24 -> 640000 | D25: =Eventos!$D$23*Eventos!$D$24 -> 1104000 | E25: =Eventos!$E$23*Eventos!$E$24 -> 1800000
A26: Taquilla bruta | B26: M MXN | C26: =Eventos!$C$25*Supuestos!$C$38/10^6 -> 1088 | D26: =Eventos!$D$25*Supuestos!$D$38/10^6 -> 2428.8 | E26: =Eventos!$E$25*Supuestos!$E$38/10^6 -> 4680 | F26: Va al club o al promotor
A27: Ventas de alimentos y bebidas | B27: M MXN | C27: =Eventos!$C$25*Supuestos!$C$40/10^6 -> 179.2 | D27: =Eventos!$D$25*Supuestos!$D$40/10^6 -> 386.4 | E27: =Eventos!$E$25*Supuestos!$E$40/10^6 -> 810
A28: Autos por evento | B28: autos | C28: =MIN(Supuestos!$C$123,Eventos!$C$24*Supuestos!$C$70) -> 5600 | D28: =MIN(Supuestos!$D$123,Eventos!$D$24*Supuestos!$D$70) -> 5688 | E28: =MIN(Supuestos!$E$123,Eventos!$E$24*Supuestos!$E$70) -> 5688
A30: NFL / fútbol americano
A31: Eventos al año | B31: eventos | C31: =Supuestos!$C$41 -> 0 | D31: =Supuestos!$D$41 -> 1 | E31: =Supuestos!$E$41 -> 1
A32: Asistencia por evento | B32: personas | C32: =MIN(Supuestos!$C$42,Supuestos!$C$61) -> 70000 | D32: =MIN(Supuestos!$D$42,Supuestos!$D$61) -> 78000 | E32: =MIN(Supuestos!$E$42,Supuestos!$E$61) -> 85000 | F32: Tope = aforo
A33: Asistentes al año | B33: personas | C33: =Eventos!$C$31*Eventos!$C$32 -> 0 | D33: =Eventos!$D$31*Eventos!$D$32 -> 78000 | E33: =Eventos!$E$31*Eventos!$E$32 -> 85000
A34: Taquilla bruta | B34: M MXN | C34: =Eventos!$C$33*Supuestos!$C$43/10^6 -> 0 | D34: =Eventos!$D$33*Supuestos!$D$43/10^6 -> 249.6 | E34: =Eventos!$E$33*Supuestos!$E$43/10^6 -> 340 | F34: Va al club o al promotor
A35: Ventas de alimentos y bebidas | B35: M MXN | C35: =Eventos!$C$33*Supuestos!$C$45/10^6 -> 0 | D35: =Eventos!$D$33*Supuestos!$D$45/10^6 -> 29.64 | E35: =Eventos!$E$33*Supuestos!$E$45/10^6 -> 40.8
A36: Autos por evento | B36: autos | C36: =MIN(Supuestos!$C$123,Eventos!$C$32*Supuestos!$C$70) -> 4900 | D36: =MIN(Supuestos!$D$123,Eventos!$D$32*Supuestos!$D$70) -> 5688 | E36: =MIN(Supuestos!$E$123,Eventos!$E$32*Supuestos!$E$70) -> 5688
A38: Festivales (días)
A39: Eventos al año | B39: eventos | C39: =Supuestos!$C$46 -> 4 | D39: =Supuestos!$D$46 -> 6 | E39: =Supuestos!$E$46 -> 10
A40: Asistencia por evento | B40: personas | C40: =MIN(Supuestos!$C$47,Supuestos!$C$61) -> 50000 | D40: =MIN(Supuestos!$D$47,Supuestos!$D$61) -> 60000 | E40: =MIN(Supuestos!$E$47,Supuestos!$E$61) -> 70000 | F40: Tope = aforo
A41: Asistentes al año | B41: personas | C41: =Eventos!$C$39*Eventos!$C$40 -> 200000 | D41: =Eventos!$D$39*Eventos!$D$40 -> 360000 | E41: =Eventos!$E$39*Eventos!$E$40 -> 700000
A42: Taquilla bruta | B42: M MXN | C42: =Eventos!$C$41*Supuestos!$C$48/10^6 -> 300 | D42: =Eventos!$D$41*Supuestos!$D$48/10^6 -> 648 | E42: =Eventos!$E$41*Supuestos!$E$48/10^6 -> 1540 | F42: Va al club o al promotor
A43: Ventas de alimentos y bebidas | B43: M MXN | C43: =Eventos!$C$41*Supuestos!$C$50/10^6 -> 56 | D43: =Eventos!$D$41*Supuestos!$D$50/10^6 -> 126 | E43: =Eventos!$E$41*Supuestos!$E$50/10^6 -> 315
A44: Autos por evento | B44: autos | C44: =MIN(Supuestos!$C$123,Eventos!$C$40*Supuestos!$C$70) -> 3500 | D44: =MIN(Supuestos!$D$123,Eventos!$D$40*Supuestos!$D$70) -> 4800 | E44: =MIN(Supuestos!$E$123,Eventos!$E$40*Supuestos!$E$70) -> 5688
A46: Modo arena: box, UFC, básquet, lucha
A47: Eventos al año | B47: eventos | C47: =Supuestos!$C$51 -> 1 | D47: =Supuestos!$D$51 -> 2 | E47: =Supuestos!$E$51 -> 4
...

Sheet Energia
A1: Energía: cuánto generan los paneles, cuánto se consume y cuánto se paga
A2: GWh = millones de kWh. Dinero en millones de MXN. Los paneles se recalcularon con pérdidas reales (la cifra anterior de 16 GWh solo en la cubierta era optimista).
A4: Concepto | B4: Unidad | C4: Conservador | D4: Base | E4: Optimista | F4: Nota / fuente
A6: 1. Rendimiento de los paneles
A7: Sol que llega (radiación horizontal) | B7: kWh/m²/año | C7: =Supuestos!$C$132 -> 1850 | D7: =Supuestos!$D$132 -> 1900 | E7: =Supuestos!$E$132 -> 2000
A8: Lo que sobrevive a las pérdidas | B8: % | C8: =(1-Supuestos!$C$133)*(1-Supuestos!$C$134)*(1-Supuestos!$C$135)*(1-Supuestos!$C$136)*(1-Supuestos!$C$137)*(1-Supuestos!$C$138)*(1-Supuestos!$C$139) -> 0.72950044 | D8: =(1-Supuestos!$D$133)*(1-Supuestos!$D$134)*(1-Supuestos!$D$135)*(1-Supuestos!$D$136)*(1-Supuestos!$D$137)*(1-Supuestos!$D$138)*(1-Supuestos!$D$139) -> 0.76936863 | E8: =(1-Supuestos!$E$133)*(1-Supuestos!$E$134)*(1-Supuestos!$E$135)*(1-Supuestos!$E$136)*(1-Supuestos!$E$137)*(1-Supuestos!$E$138)*(1-Supuestos!$E$139) -> 0.81913267 | F8: Producto de las 7 pérdidas de Supuestos
A9: Rendimiento en cubierta y pérgolas | B9: kWh/kWp/año | C9: =Energia!$C$7*Energia!$C$8 -> 1349.5758 | D9: =Energia!$D$7*Energia!$D$8 -> 1461.8004 | E9: =Energia!$E$7*Energia!$E$8 -> 1638.2653
A10: Rendimiento del vidrio fotovoltaico vertical | B10: kWh/kWp/año | C10: =Energia!$C$9*Supuestos!$C$145 -> 485.84729 | D10: =Energia!$D$9*Supuestos!$D$145 -> 555.48415 | E10: =Energia!$E$9*Supuestos!$E$145 -> 655.30614
A12: 2. Generación solar
A13: Potencia en la cubierta del estadio | B13: kWp | C13: =Supuestos!$C$140*Supuestos!$C$143 -> 8172.41 | D13: =Supuestos!$D$140*Supuestos!$D$143 -> 8653.14 | E13: =Supuestos!$E$140*Supuestos!$E$143 -> 9133.87
A14: Potencia en pérgolas de la azotea | B14: kWp | C14: =Supuestos!$C$141*Supuestos!$C$143 -> 833 | D14: =Supuestos!$D$141*Supuestos!$D$143 -> 882 | E14: =Supuestos!$E$141*Supuestos!$E$143 -> 931
A15: Potencia en la fachada (vidrio fotovoltaico) | B15: kWp | C15: =Supuestos!$C$142*Supuestos!$C$144 -> 3575.76 | D15: =Supuestos!$D$142*Supuestos!$D$144 -> 3575.76 | E15: =Supuestos!$E$142*Supuestos!$E$144 -> 3575.76
A16: Potencia total | B16: kWp | C16: =Energia!$C$13+Energia!$C$14+Energia!$C$15 -> 12581.17 | D16: =Energia!$D$13+Energia!$D$14+Energia!$D$15 -> 13110.9 | E16: =Energia!$E$13+Energia!$E$14+Energia!$E$15 -> 13640.63
A17: Generación de la cubierta del estadio | B17: GWh/año | C17: =Energia!$C$13*Energia!$C$9/10^6 -> 11.029287 | D17: =Energia!$D$13*Energia!$D$9/10^6 -> 12.649163 | E17: =Energia!$E$13*Energia!$E$9/10^6 -> 14.963703
A18: Generación de las pérgolas | B18: GWh/año | C18: =Energia!$C$14*Energia!$C$9/10^6 -> 1.1241966 | D18: =Energia!$D$14*Energia!$D$9/10^6 -> 1.2893079 | E18: =Energia!$E$14*Energia!$E$9/10^6 -> 1.525225
A19: Generación de la fachada | B19: GWh/año | C19: =Energia!$C$15*Energia!$C$10/10^6 -> 1.7372733 | D19: =Energia!$D$15*Energia!$D$10/10^6 -> 1.986278 | E19: =Energia!$E$15*Energia!$E$10/10^6 -> 2.3432175
A20: Generación solar total | B20: GWh/año | C20: =Energia!$C$17+Energia!$C$18+Energia!$C$19 -> 13.890757 | D20: =Energia!$D$17+Energia!$D$18+Energia!$D$19 -> 15.924749 | E20: =Energia!$E$17+Energia!$E$18+Energia!$E$19 -> 18.832145
A21: Lo que darían sin ninguna pérdida | B21: GWh/año | C21: =(Energia!$C$13+Energia!$C$14)*Energia!$C$7/10^6+Energia!$C$15*Energia!$C$7*Supuestos!$C$145/10^6 -> 19.041465 | D21: =(Energia!$D$13+Energia!$D$14)*Energia!$D$7/10^6+Energia!$D$15*Energia!$D$7*Supuestos!$D$145/10^6 -> 20.698465 | E21: =(Energia!$E$13+Energia!$E$14)*Energia!$E$7/10^6+Energia!$E$15*Energia!$E$7*Supuestos!$E$145/10^6 -> 22.990348 | F21: Potencia × sol, sin pérdidas
A22: Energía solar que se pierde (calor, polvo, sombra, inversores, cables) | B22: GWh/año | C22: =Energia!$C$21-Energia!$C$20 -> 5.1507079 | D22: =Energia!$D$21-Energia!$D$20 -> 4.7737154 | E22: =Energia!$E$21-Energia!$E$20 -> 4.1582029
A23: Pérdida por degradación al año 10 | B23: GWh/año | C23: =Energia!$C$20*(1-(1-Supuestos!$C$146)^9) -> 0.61272714 | D23: =Energia!$D$20*(1-(1-Supuestos!$D$146)^9) -> 0.70244741 | E23: =Energia!$E$20*(1-(1-Supuestos!$E$146)^9) -> 0.83069386
A24: Generación en el año 30 | B24: GWh/año | C24: =Energia!$C$20*(1-Supuestos!$C$146)^29 -> 12.011445 | D24: =Energia!$D$20*(1-Supuestos!$D$146)^29 -> 13.770254 | E24: =Energia!$E$20*(1-Supuestos!$E$146)^29 -> 16.284301
A26: 3. Consumo
A27: Estadio | B27: GWh/año | C27: =(Supuestos!$C$147*8760/1000+Supuestos!$C$148*Eventos!$C$63)/1000 -> 8.652 | D27: =(Supuestos!$D$147*8760/1000+Supuestos!$D$148*Eventos!$D$63)/1000 -> 8.594 | E27: =(Supuestos!$E$147*8760/1000+Supuestos!$E$148*Eventos!$E$63)/1000 -> 8.721
A28: Plaza Sakbé (locales y áreas comunes) | B28: GWh/año | C28: =Supuestos!$C$102*Supuestos!$C$149/10^6 -> 52.12134 | D28: =Supuestos!$D$102*Supuestos!$D$149/10^6 -> 44.39966 | E28: =Supuestos!$E$102*Supuestos!$E$149/10^6 -> 38.6084
A29: Estacionamiento subterráneo | B29: GWh/año | C29: =Supuestos!$C$151*Supuestos!$C$150/10^6 -> 4.188324 | D29: =Supuestos!$D$151*Supuestos!$D$150/10^6 -> 3.839297 | E29: =Supuestos!$E$151*Supuestos!$E$150/10^6 -> 3.49027
A30: Carga de autos eléctricos | B30: GWh/año | C30: =Supuestos!$C$127*Supuestos!$C$128*365/10^6 -> 1.022 | D30: =Supuestos!$D$127*Supuestos!$D$128*365/10^6 -> 1.752 | E30: =Supuestos!$E$127*Supuestos!$E$128*365/10^6 -> 2.628
A31: Consumo total del conjunto | B31: GWh/año | C31: =Energia!$C$27+Energia!$C$28+Energia!$C$29+Energia!$C$30 -> 65.983664 | D31: =Energia!$D$27+Energia!$D$28+Energia!$D$29+Energia!$D$30 -> 58.584957 | E31: =Energia!$E$27+Energia!$E$28+Energia!$E$29+Energia!$E$30 -> 53.44767
A33: 4. Balance de todo el conjunto
A34: Parte del consumo que cubren los paneles | B34: % | C34: =Energia!$C$20/Energia!$C$31 -> 0.21051812 | D34: =Energia!$D$20/Energia!$D$31 -> 0.27182318 | E34: =Energia!$E$20/Energia!$E$31 -> 0.35234735
A35: Paneles vs. consumo del estadio solo | B35: % | C35: =Energia!$C$17/Energia!$C$27 -> 1.2747673 | D35: =Energia!$D$17/Energia!$D$27 -> 1.4718598 | E35: =Energia!$E$17/Energia!$E$27 -> 1.7158242 | F35: La cubierta sola genera más de lo que gasta el estadio
A36: Energía que hay que comprar a la red | B36: GWh/año | C36: =MAX(0,Energia!$C$31-Energia!$C$20) -> 52.092907 | D36: =MAX(0,Energia!$D$31-Energia!$D$20) -> 42.660208 | E36: =MAX(0,Energia!$E$31-Energia!$E$20) -> 34.615525
A37: Costo de la energía comprada (todo el conjunto) | B37: M MXN/año | C37: =Energia!$C$36*Supuestos!$C$153 -> 161.48801 | D37: =Energia!$D$36*Supuestos!$D$153 -> 119.44858 | E37: =Energia!$E$36*Supuestos!$E$153 -> 86.538812
A38: Lo que costaría toda la energía sin paneles | B38: M MXN/año | C38: =Energia!$C$31*Supuestos!$C$153 -> 204.54936 | D38: =Energia!$D$31*Supuestos!$D$153 -> 164.03788 | E38: =Energia!$E$31*Supuestos!$E$153 -> 133.61918
A40: 5. Quién paga qué
A41: Consumo que pagan los locatarios (su medidor) | B41: GWh/año | C41: =Energia!$C$28*Supuestos!$C$152 -> 33.878871 | D41: =Energia!$D$28*Supuestos!$D$152 -> 28.859779 | E41: =Energia!$E$28*Supuestos!$E$152 -> 25.09546
A42: Consumo que paga el dueño | B42: GWh/año | C42: =Energia!$C$31-Energia!$C$41 -> 32.104793 | D42: =Energia!$D$31-Energia!$D$41 -> 29.725178 | E42: =Energia!$E$31-Energia!$E$41 -> 28.35221 | F42: Estadio + áreas comunes + estacionamiento + cargadores
A43: Energía que compra el dueño | B43: GWh/año | C43: =MAX(0,Energia!$C$42-Energia!$C$20) -> 18.214036 | D43: =MAX(0,Energia!$D$42-Energia!$D$20) -> 13.800429 | E43: =MAX(0,Energia!$E$42-Energia!$E$20) -> 9.5200649
A44: Costo de energía del dueño | B44: M MXN/año | C44: =Energia!$C$43*Supuestos!$C$153 -> 56.463512 | D44: =Energia!$D$43*Supuestos!$D$153 -> 38.6412 | E44: =Energia!$E$43*Supuestos!$E$153 -> 23.800162
A45: Costo de energía de los locatarios | B45: M MXN/año | C45: =Energia!$C$41*Supuestos!$C$153 -> 105.0245 | D45: =Energia!$D$41*Supuestos!$D$153 -> 80.807381 | E45: =Energia!$E$41*Supuestos!$E$153 -> 62.73865 | F45: Lo pagan ellos
A47: 6. Lo que valen los paneles
...

Sheet Agua
A1: Agua: consumo, lluvia, reúso y costo
A2: m³ por año. Dinero en millones de MXN.
A4: Concepto | B4: Unidad | C4: Conservador | D4: Base | E4: Optimista | F4: Nota / fuente
A6: Consumo
A7: Estadio | B7: m³/año | C7: =Supuestos!$C$165*Eventos!$C$63+Supuestos!$C$166 -> 78400 | D7: =Supuestos!$D$165*Eventos!$D$63+Supuestos!$D$166 -> 91800 | E7: =Supuestos!$E$165*Eventos!$E$63+Supuestos!$E$166 -> 105000
A8: Plaza Sakbé | B8: m³/año | C8: =Supuestos!$C$102*Supuestos!$C$167 -> 231650.4 | D8: =Supuestos!$D$102*Supuestos!$D$167 -> 212346.2 | E8: =Supuestos!$E$102*Supuestos!$E$167 -> 193042
A9: Riego del parque y jardines | B9: m³/año | C9: =Supuestos!$C$168*Supuestos!$C$169 -> 30769.75 | D9: =Supuestos!$D$168*Supuestos!$D$169 -> 28531.95 | E9: =Supuestos!$E$168*Supuestos!$E$169 -> 25175.25
A10: Consumo total | B10: m³/año | C10: =Agua!$C$7+Agua!$C$8+Agua!$C$9 -> 340820.15 | D10: =Agua!$D$7+Agua!$D$8+Agua!$D$9 -> 332678.15 | E10: =Agua!$E$7+Agua!$E$8+Agua!$E$9 -> 323217.25
A12: De dónde sale
A13: Lluvia captada | B13: m³/año | C13: =Supuestos!$C$170*Supuestos!$C$171*Supuestos!$C$172 -> 46984.8 | D13: =Supuestos!$D$170*Supuestos!$D$171*Supuestos!$D$172 -> 54815.6 | E13: =Supuestos!$E$170*Supuestos!$E$171*Supuestos!$E$172 -> 62646.4 | F13: Cisternas de 7,700 m³ en el sótano
A14: Agua gris tratada y reusada | B14: m³/año | C14: =(Agua!$C$7+Agua!$C$8)*Supuestos!$C$173 -> 93015.12 | D14: =(Agua!$D$7+Agua!$D$8)*Supuestos!$D$173 -> 121658.48 | E14: =(Agua!$E$7+Agua!$E$8)*Supuestos!$E$173 -> 149021
A15: Agua comprada a la red | B15: m³/año | C15: =MAX(0,Agua!$C$10-Agua!$C$13-Agua!$C$14) -> 200820.23 | D15: =MAX(0,Agua!$D$10-Agua!$D$13-Agua!$D$14) -> 156204.07 | E15: =MAX(0,Agua!$E$10-Agua!$E$13-Agua!$E$14) -> 111549.85
A16: Parte que no viene de la red | B16: % | C16: =1-Agua!$C$15/Agua!$C$10 -> 0.4107736 | D16: =1-Agua!$D$15/Agua!$D$10 -> 0.5304649 | E16: =1-Agua!$E$15/Agua!$E$10 -> 0.65487656
A18: Costo
A19: Agua comprada | B19: M MXN/año | C19: =Agua!$C$15*Supuestos!$C$174/10^6 -> 11.045113 | D19: =Agua!$D$15*Supuestos!$D$174/10^6 -> 7.0291831 | E19: =Agua!$E$15*Supuestos!$E$174/10^6 -> 3.9042448
A20: Tratamiento del agua reusada | B20: M MXN/año | C20: =Agua!$C$14*Supuestos!$C$175/10^6 -> 1.1161814 | D20: =Agua!$D$14*Supuestos!$D$175/10^6 -> 1.2165848 | E20: =Agua!$E$14*Supuestos!$E$175/10^6 -> 1.192168
A21: Costo total del agua | B21: M MXN/año | C21: =Agua!$C$19+Agua!$C$20 -> 12.161294 | D21: =Agua!$D$19+Agua!$D$20 -> 8.2457679 | E21: =Agua!$E$19+Agua!$E$20 -> 5.0964127 | F21: El dueño la paga y la recupera en parte con la cuota de mantenimiento
A22: Ahorro por lluvia y reúso | B22: M MXN/año | C22: =(Agua!$C$13+Agua!$C$14)*Supuestos!$C$174/10^6-Agua!$C$20 -> 6.5838142 | D22: =(Agua!$D$13+Agua!$D$14)*Supuestos!$D$174/10^6-Agua!$D$20 -> 6.7247488 | E22: =(Agua!$E$13+Agua!$E$14)*Supuestos!$E$174/10^6-Agua!$E$20 -> 6.216191

Sheet Ingresos
A1: Todas las fuentes de ingreso (año estable de operación)
A2: Millones de MXN por año. Lo que entra al dueño del estadio y la plaza (no la taquilla completa del promotor).
A4: Concepto | B4: Unidad | C4: Conservador | D4: Base | E4: Optimista | F4: Nota / fuente
A6: A. Estadio: eventos
A7: Renta por partidos de fútbol de liga | B7: M MXN/año | C7: =Eventos!$C$10*Supuestos!$C$29 -> 42.75 | D7: =Eventos!$D$10*Supuestos!$D$29 -> 100.224 | E7: =Eventos!$E$10*Supuestos!$E$29 -> 214.2 | F7: % de taquilla
A8: Renta por partidos de selección e internacionales | B8: M MXN/año | C8: =Eventos!$C$18*Supuestos!$C$34 -> 11.76 | D8: =Eventos!$D$18*Supuestos!$D$34 -> 30.6 | E8: =Eventos!$E$18*Supuestos!$E$34 -> 64.8 | F8: % de taquilla
A9: Renta por conciertos | B9: M MXN/año | C9: =Eventos!$C$26*Supuestos!$C$39 -> 87.04 | D9: =Eventos!$D$26*Supuestos!$D$39 -> 242.88 | E9: =Eventos!$E$26*Supuestos!$E$39 -> 561.6 | F9: % de taquilla (venue fee)
A10: Renta por NFL / fútbol americano | B10: M MXN/año | C10: =Eventos!$C$31*Supuestos!$C$44 -> 0 | D10: =Eventos!$D$31*Supuestos!$D$44 -> 60 | E10: =Eventos!$E$31*Supuestos!$E$44 -> 80
A11: Renta por festivales | B11: M MXN/año | C11: =Eventos!$C$39*Supuestos!$C$49 -> 40 | D11: =Eventos!$D$39*Supuestos!$D$49 -> 90 | E11: =Eventos!$E$39*Supuestos!$E$49 -> 200
A12: Renta por eventos de arena (box, UFC, básquet, lucha) | B12: M MXN/año | C12: =Eventos!$C$47*Supuestos!$C$54 -> 8 | D12: =Eventos!$D$47*Supuestos!$D$54 -> 24 | E12: =Eventos!$E$47*Supuestos!$E$54 -> 72
A13: Renta por otros eventos (religiosos, corporativos, graduaciones, e-sports) | B13: M MXN/año | C13: =Eventos!$C$55*Supuestos!$C$59 -> 8 | D13: =Eventos!$D$55*Supuestos!$D$59 -> 24 | E13: =Eventos!$E$55*Supuestos!$E$59 -> 48
A14: Cuota de instalación por boleto | B14: M MXN/año | C14: =Eventos!$C$65*Supuestos!$C$65/10^6 -> 37.2 | D14: =Eventos!$D$65*Supuestos!$D$65/10^6 -> 88.1 | E14: =Eventos!$E$65*Supuestos!$E$65/10^6 -> 214.55 | F14: Todos los eventos menos fútbol
A15: Comisión de boletaje (rebate) | B15: M MXN/año | C15: =Eventos!$C$66*Supuestos!$C$66 -> 39.53 | D15: =Eventos!$D$66*Supuestos!$D$66 -> 136.908 | E15: =Eventos!$E$66*Supuestos!$E$66 -> 357.92
A17: B. Estadio: lo que gasta el público
A18: Alimentos y bebidas (participación de la concesión) | B18: M MXN/año | C18: =Eventos!$C$67*Supuestos!$C$62 -> 154.8925 | D18: =Eventos!$D$67*Supuestos!$D$62 -> 387.616 | E18: =Eventos!$E$67*Supuestos!$E$62 -> 883.17
A19: Mercancía (participación) | B19: M MXN/año | C19: =Eventos!$C$68*Supuestos!$C$64 -> 8.78 | D19: =Eventos!$D$68*Supuestos!$D$64 -> 26.9424 | E19: =Eventos!$E$68*Supuestos!$E$64 -> 69.66
A20: Paquetes VIP y hospitalidad por evento | B20: M MXN/año | C20: =Supuestos!$C$67*Eventos!$C$63*Supuestos!$C$68*Supuestos!$C$69/10^6 -> 31.5 | D20: =Supuestos!$D$67*Eventos!$D$63*Supuestos!$D$68*Supuestos!$D$69/10^6 -> 87 | E20: =Supuestos!$E$67*Eventos!$E$63*Supuestos!$E$68*Supuestos!$E$69/10^6 -> 202.125
A21: Estacionamiento en días de evento | B21: M MXN/año | C21: =Eventos!$C$69*Supuestos!$C$71/10^6 -> 30.73 | D21: =Eventos!$D$69*Supuestos!$D$71/10^6 -> 69.152 | E21: =Eventos!$E$69*Supuestos!$E$71/10^6 -> 127.2888
A23: C. Estadio: palcos, patrocinios y publicidad
A24: Palcos (renta anual) | B24: M MXN/año | C24: =Supuestos!$C$76*Supuestos!$C$77*Supuestos!$C$78 -> 224 | D24: =Supuestos!$D$76*Supuestos!$D$77*Supuestos!$D$78 -> 405 | E24: =Supuestos!$E$76*Supuestos!$E$77*Supuestos!$E$78 -> 585.2
A25: Asientos club (membresía anual) | B25: M MXN/año | C25: =Supuestos!$C$79*Supuestos!$C$80*Supuestos!$C$81/10^6 -> 101.25 | D25: =Supuestos!$D$79*Supuestos!$D$80*Supuestos!$D$81/10^6 -> 204 | E25: =Supuestos!$E$79*Supuestos!$E$80*Supuestos!$E$81/10^6 -> 356.25
A26: Derechos de nombre del estadio | B26: M MXN/año | C26: =Supuestos!$C$82*Supuestos!$C$7 -> 74 | D26: =Supuestos!$D$82*Supuestos!$D$7 -> 111 | E26: =Supuestos!$E$82*Supuestos!$E$7 -> 148
A27: Patrocinios oficiales y exclusividad de bebidas | B27: M MXN/año | C27: =Supuestos!$C$83 -> 100 | D27: =Supuestos!$D$83 -> 150 | E27: =Supuestos!$E$83 -> 200
A28: Publicidad en pantallas y anillos LED | B28: M MXN/año | C28: =Supuestos!$C$84 -> 20 | D28: =Supuestos!$D$84 -> 35 | E28: =Supuestos!$E$84 -> 50
A29: Fachada LED exterior | B29: M MXN/año | C29: =Supuestos!$C$85 -> 40 | D29: =Supuestos!$D$85 -> 60 | E29: =Supuestos!$E$85 -> 90
A31: D. Estadio: días sin evento
A32: Tours y museo del deporte | B32: M MXN/año | C32: =Supuestos!$C$88*Supuestos!$C$89/10^6 -> 20 | D32: =Supuestos!$D$88*Supuestos!$D$89/10^6 -> 37.5 | E32: =Supuestos!$E$88*Supuestos!$E$89/10^6 -> 66
A33: Caminata sobre la cubierta | B33: M MXN/año | C33: =Supuestos!$C$90*Supuestos!$C$91/10^6 -> 18 | D33: =Supuestos!$D$90*Supuestos!$D$91/10^6 -> 33 | E33: =Supuestos!$E$90*Supuestos!$E$91/10^6 -> 58.5
A34: Congresos, convenciones y eventos privados | B34: M MXN/año | C34: =Supuestos!$C$92*Supuestos!$C$93/10^6 -> 21.6 | D34: =Supuestos!$D$92*Supuestos!$D$93/10^6 -> 50 | E34: =Supuestos!$E$92*Supuestos!$E$93/10^6 -> 96
A35: Renta de cancha y vestidores | B35: M MXN/año | C35: =Supuestos!$C$94*Supuestos!$C$95/10^6 -> 4.8 | D35: =Supuestos!$D$94*Supuestos!$D$95/10^6 -> 9 | E35: =Supuestos!$E$94*Supuestos!$E$95/10^6 -> 14.4
A36: Filmación, comerciales y fotos | B36: M MXN/año | C36: =Supuestos!$C$96 -> 10 | D36: =Supuestos!$D$96 -> 20 | E36: =Supuestos!$E$96 -> 30
A37: Contenido digital, app y datos | B37: M MXN/año | C37: =Supuestos!$C$97 -> 8 | D37: =Supuestos!$D$97 -> 15 | E37: =Supuestos!$E$97 -> 25
A38: Renta de antenas y red | B38: M MXN/año | C38: =Supuestos!$C$98 -> 6 | D38: =Supuestos!$D$98 -> 10 | E38: =Supuestos!$E$98 -> 15
A40: E. Plaza Sakbé
A41: Renta: tiendas | B41: M MXN/año | C41: =Supuestos!$C$102*Supuestos!$C$103*Supuestos!$C$104*Supuestos!$C$105*12*Supuestos!$C$116/10^6 -> 423.97583 | D41: =Supuestos!$D$102*Supuestos!$D$103*Supuestos!$D$104*Supuestos!$D$105*12*Supuestos!$D$116/10^6 -> 609.81968 | E41: =Supuestos!$E$102*Supuestos!$E$103*Supuestos!$E$104*Supuestos!$E$105*12*Supuestos!$E$116/10^6 -> 808.08926
A42: Renta: restaurantes y terrazas | B42: M MXN/año | C42: =Supuestos!$C$102*Supuestos!$C$103*Supuestos!$C$106*Supuestos!$C$107*12*Supuestos!$C$116/10^6 -> 211.98791 | D42: =Supuestos!$D$102*Supuestos!$D$103*Supuestos!$D$106*Supuestos!$D$107*12*Supuestos!$D$116/10^6 -> 298.13406 | E42: =Supuestos!$E$102*Supuestos!$E$103*Supuestos!$E$106*Supuestos!$E$107*12*Supuestos!$E$116/10^6 -> 389.08001
A43: Renta: cines | B43: M MXN/año | C43: =Supuestos!$C$102*Supuestos!$C$103*Supuestos!$C$108*Supuestos!$C$109*12*Supuestos!$C$116/10^6 -> 47.108425 | D43: =Supuestos!$D$102*Supuestos!$D$103*Supuestos!$D$108*Supuestos!$D$109*12*Supuestos!$D$116/10^6 -> 67.757742 | E43: =Supuestos!$E$102*Supuestos!$E$103*Supuestos!$E$108*Supuestos!$E$109*12*Supuestos!$E$116/10^6 -> 89.787695
A44: Renta: gimnasio y centro deportivo | B44: M MXN/año | C44: =Supuestos!$C$102*Supuestos!$C$103*Supuestos!$C$110*Supuestos!$C$111*12*Supuestos!$C$116/10^6 -> 58.885532 | D44: =Supuestos!$D$102*Supuestos!$D$103*Supuestos!$D$110*Supuestos!$D$111*12*Supuestos!$D$116/10^6 -> 81.30929 | E44: =Supuestos!$E$102*Supuestos!$E$103*Supuestos!$E$110*Supuestos!$E$111*12*Supuestos!$E$116/10^6 -> 104.75231
A45: Renta: clínica, guardería y museo | B45: M MXN/año | C45: =Supuestos!$C$102*Supuestos!$C$103*Supuestos!$C$112*Supuestos!$C$113*12*Supuestos!$C$116/10^6 -> 65.951795 | D45: =Supuestos!$D$102*Supuestos!$D$103*Supuestos!$D$112*Supuestos!$D$113*12*Supuestos!$D$116/10^6 -> 94.860839 | E45: =Supuestos!$E$102*Supuestos!$E$103*Supuestos!$E$112*Supuestos!$E$113*12*Supuestos!$E$116/10^6 -> 125.70277
A46: Renta: oficinas y coworking | B46: M MXN/año | C46: =Supuestos!$C$102*Supuestos!$C$103*Supuestos!$C$114*Supuestos!$C$115*12*Supuestos!$C$116/10^6 -> 179.01202 | D46: =Supuestos!$D$102*Supuestos!$D$103*Supuestos!$D$114*Supuestos!$D$115*12*Supuestos!$D$116/10^6 -> 243.92787 | E46: =Supuestos!$E$102*Supuestos!$E$103*Supuestos!$E$114*Supuestos!$E$115*12*Supuestos!$E$116/10^6 -> 329.22155
...

Sheet Costos_Operacion
A1: Costos de operación (año estable)
A2: Millones de MXN por año.
A4: Concepto | B4: Unidad | C4: Conservador | D4: Base | E4: Optimista | F4: Nota / fuente
A6: Personal
A7: Personal permanente (estadio y corporativo) | B7: M MXN/año | C7: =Supuestos!$C$178*Supuestos!$C$179/10^6 -> 99 | D7: =Supuestos!$D$178*Supuestos!$D$179/10^6 -> 75.6 | E7: =Supuestos!$E$178*Supuestos!$E$179/10^6 -> 68
A8: Personal por evento | B8: M MXN/año | C8: =Supuestos!$C$72*Supuestos!$C$73*Eventos!$C$63/10^6 -> 111.72 | D8: =Supuestos!$D$72*Supuestos!$D$73*Eventos!$D$63/10^6 -> 130.5 | E8: =Supuestos!$E$72*Supuestos!$E$73*Eventos!$E$63/10^6 -> 143.99
A10: Energía y agua
A11: Energía comprada a la red (parte del dueño) | B11: M MXN/año | C11: =Energia!$C$44 -> 56.463512 | D11: =Energia!$D$44 -> 38.6412 | E11: =Energia!$E$44 -> 23.800162 | F11: Ya descuenta los paneles solares
A12: Operación y limpieza de paneles | B12: M MXN/año | C12: =Energia!$C$50 -> 3.774351 | D12: =Energia!$D$50 -> 3.277725 | E12: =Energia!$E$50 -> 2.728126
A13: Agua (comprada + tratamiento) | B13: M MXN/año | C13: =Agua!$C$21 -> 12.161294 | D13: =Agua!$D$21 -> 8.2457679 | E13: =Agua!$E$21 -> 5.0964127
A15: Mantenimiento
A16: Mantenimiento del edificio y sus sistemas | B16: M MXN/año | C16: =Supuestos!$C$9*Supuestos!$C$180 -> 446.82 | D16: =Supuestos!$D$9*Supuestos!$D$180 -> 372.35 | E16: =Supuestos!$E$9*Supuestos!$E$180 -> 335.115
A17: Contratos de escaleras eléctricas | B17: M MXN/año | C17: =Supuestos!$C$181*Supuestos!$C$182/10^6 -> 25.76 | D17: =Supuestos!$D$181*Supuestos!$D$182/10^6 -> 22.08 | E17: =Supuestos!$E$181*Supuestos!$E$182/10^6 -> 18.4
A18: Contratos de elevadores | B18: M MXN/año | C18: =Supuestos!$C$183*Supuestos!$C$184/10^6 -> 18.54 | D18: =Supuestos!$D$183*Supuestos!$D$184/10^6 -> 16.48 | E18: =Supuestos!$E$183*Supuestos!$E$184/10^6 -> 14.42
A19: Techo retráctil | B19: M MXN/año | C19: =Supuestos!$C$185 -> 20 | D19: =Supuestos!$D$185 -> 15 | E19: =Supuestos!$E$185 -> 12
A20: Cancha | B20: M MXN/año | C20: =Supuestos!$C$186 -> 30 | D20: =Supuestos!$D$186 -> 25 | E20: =Supuestos!$E$186 -> 20
A21: Jardinería y árboles | B21: M MXN/año | C21: =Supuestos!$C$187 -> 18 | D21: =Supuestos!$D$187 -> 15 | E21: =Supuestos!$E$187 -> 12
A22: Reserva para reposiciones mayores | B22: M MXN/año | C22: =Supuestos!$C$9*Supuestos!$C$198 -> 223.41 | D22: =Supuestos!$D$9*Supuestos!$D$198 -> 186.175 | E22: =Supuestos!$E$9*Supuestos!$E$198 -> 148.94
A24: Servicios
A25: Seguridad permanente 24/7 | B25: M MXN/año | C25: =Supuestos!$C$188 -> 55 | D25: =Supuestos!$D$188 -> 45 | E25: =Supuestos!$E$188 -> 40
A26: Limpieza permanente | B26: M MXN/año | C26: =Supuestos!$C$189 -> 30 | D26: =Supuestos!$D$189 -> 25 | E26: =Supuestos!$E$189 -> 22
A27: Recolección de residuos | B27: M MXN/año | C27: =Supuestos!$C$190 -> 12 | D27: =Supuestos!$D$190 -> 10 | E27: =Supuestos!$E$190 -> 8
A28: Telecomunicaciones, WiFi y sistemas | B28: M MXN/año | C28: =Supuestos!$C$191 -> 15 | D28: =Supuestos!$D$191 -> 12 | E28: =Supuestos!$E$191 -> 10
A29: Operación del estacionamiento | B29: M MXN/año | C29: =(Ingresos!$C$21+Ingresos!$C$51)*Supuestos!$C$197 -> 25.044267 | D29: =(Ingresos!$D$21+Ingresos!$D$51)*Supuestos!$D$197 -> 38.97591 | E29: =(Ingresos!$E$21+Ingresos!$E$51)*Supuestos!$E$197 -> 51.528571
A30: Operación de áreas comunes de la plaza (limpieza, seguridad, parque) | B30: M MXN/año | C30: =Ingresos!$C$52 -> 176.6566 | D30: =Ingresos!$D$52 -> 230.37632 | E30: =Ingresos!$E$52 -> 284.3277 | F30: Igual a la cuota de mantenimiento que pagan los locatarios
A32: Administración, seguros e impuestos locales
A33: Administración, marketing y ventas | B33: M MXN/año | C33: =Supuestos!$C$194 -> 150 | D33: =Supuestos!$D$194 -> 120 | E33: =Supuestos!$E$194 -> 100
A34: Comisiones por venta de patrocinios, naming y palcos | B34: M MXN/año | C34: =(Ingresos!$C$26+Ingresos!$C$27+Ingresos!$C$24+Ingresos!$C$25)*Supuestos!$C$195 -> 59.91 | D34: =(Ingresos!$D$26+Ingresos!$D$27+Ingresos!$D$24+Ingresos!$D$25)*Supuestos!$D$195 -> 87 | E34: =(Ingresos!$E$26+Ingresos!$E$27+Ingresos!$E$24+Ingresos!$E$25)*Supuestos!$E$195 -> 103.156
A35: Comisión y promoción de la plaza | B35: M MXN/año | C35: =Ingresos!$C$64*Supuestos!$C$196 -> 53.624934 | D35: =Ingresos!$D$64*Supuestos!$D$196 -> 58.24049 | E35: =Ingresos!$E$64*Supuestos!$E$196 -> 66.022831
A36: Seguros | B36: M MXN/año | C36: =Supuestos!$C$8*Supuestos!$C$192 -> 95.841 | D36: =Supuestos!$D$8*Supuestos!$D$192 -> 79.8675 | E36: =Supuestos!$E$8*Supuestos!$E$192 -> 63.894
A37: Predial | B37: M MXN/año | C37: =Supuestos!$C$8*Supuestos!$C$193 -> 53.245 | D37: =Supuestos!$D$8*Supuestos!$D$193 -> 53.245 | E37: =Supuestos!$E$8*Supuestos!$E$193 -> 42.596
A39: Totales
A40: Subtotal | B40: M MXN/año | C40: =Costos_Operacion!$C$7+Costos_Operacion!$C$8+Costos_Operacion!$C$11+Costos_Operacion!$C$12+Costos_Operacion!$C$13+Costos_Operacion!$C$16+Costos_Operacion!$C$17+Costos_Operacion!$C$18+Costos_Operacion!$C$19+Costos_Operacion!$C$20+Costos_Operacion!$C$21+Costos_Operacion!$C$22+Costos_Operacion!$C$25+Costos_Operacion!$C$26+Costos_Operacion!$C$27+Costos_Operacion!$C$28+Costos_Operacion!$C$29+Costos_Operacion!$C$30+Costos_Operacion!$C$33+Costos_Operacion!$C$34+Costos_Operacion!$C$35+Costos_Operacion!$C$36+Costos_Operacion!$C$37 -> 1791.971 | D40: =Costos_Operacion!$D$7+Costos_Operacion!$D$8+Costos_Operacion!$D$11+Costos_Operacion!$D$12+Costos_Operacion!$D$13+Costos_Operacion!$D$16+Costos_Operacion!$D$17+Costos_Operacion!$D$18+Costos_Operacion!$D$19+Costos_Operacion!$D$20+Costos_Operacion!$D$21+Costos_Operacion!$D$22+Costos_Operacion!$D$25+Costos_Operacion!$D$26+Costos_Operacion!$D$27+Costos_Operacion!$D$28+Costos_Operacion!$D$29+Costos_Operacion!$D$30+Costos_Operacion!$D$33+Costos_Operacion!$D$34+Costos_Operacion!$D$35+Costos_Operacion!$D$36+Costos_Operacion!$D$37 -> 1668.0549 | E40: =Costos_Operacion!$E$7+Costos_Operacion!$E$8+Costos_Operacion!$E$11+Costos_Operacion!$E$12+Costos_Operacion!$E$13+Costos_Operacion!$E$16+Costos_Operacion!$E$17+Costos_Operacion!$E$18+Costos_Operacion!$E$19+Costos_Operacion!$E$20+Costos_Operacion!$E$21+Costos_Operacion!$E$22+Costos_Operacion!$E$25+Costos_Operacion!$E$26+Costos_Operacion!$E$27+Costos_Operacion!$E$28+Costos_Operacion!$E$29+Costos_Operacion!$E$30+Costos_Operacion!$E$33+Costos_Operacion!$E$34+Costos_Operacion!$E$35+Costos_Operacion!$E$36+Costos_Operacion!$E$37 -> 1596.0148
A41: Imprevistos | B41: M MXN/año | C41: =Costos_Operacion!$C$40*Supuestos!$C$199 -> 89.598548 | D41: =Costos_Operacion!$D$40*Supuestos!$D$199 -> 50.041647 | E41: =Costos_Operacion!$E$40*Supuestos!$E$199 -> 31.920296
A42: COSTOS DE OPERACIÓN TOTALES | B42: M MXN/año | C42: =Costos_Operacion!$C$40+Costos_Operacion!$C$41 -> 1881.5695 | D42: =Costos_Operacion!$D$40+Costos_Operacion!$D$41 -> 1718.0966 | E42: =Costos_Operacion!$E$40+Costos_Operacion!$E$41 -> 1627.9351
A44: Resultado de operación
A45: Ingresos totales | B45: M MXN/año | C45: =Ingresos!$C$68 -> 2498.366 | D45: =Ingresos!$D$68 -> 4466.4375 | E45: =Ingresos!$E$68 -> 7499.5059
A46: EBITDA (lo que queda antes de impuestos y de pagar la obra) | B46: M MXN/año | C46: =Costos_Operacion!$C$45-Costos_Operacion!$C$42 -> 616.79651 | D46: =Costos_Operacion!$D$45-Costos_Operacion!$D$42 -> 2748.3409 | E46: =Costos_Operacion!$E$45-Costos_Operacion!$E$42 -> 5871.5708
A47: Margen | B47: % | C47: =Costos_Operacion!$C$46/Costos_Operacion!$C$45 -> 0.24687996 | D47: =Costos_Operacion!$D$46/Costos_Operacion!$D$45 -> 0.61533178 | E47: =Costos_Operacion!$E$46/Costos_Operacion!$E$45 -> 0.78292769

Sheet Flujo_30_anios
A1: Flujo de efectivo: 4 años de obra + 30 años de operación
A2: Millones de MXN de 2026. Los ingresos y costos estables vienen de las hojas Ingresos y Costos_Operacion; los paneles pierden 0.5 % al año y esa energía se compra a la red.
A4: Escenario Conservador
A5: Año | C5: Obra 1 | D5: Obra 2 | E5: Obra 3 | F5: Obra 4 | G5: 1 | H5: 2 | I5: 3 | J5: 4 | K5: 5 | L5: 6 | M5: 7 | N5: 8 | O5: 9 | P5: 10 | Q5: 11 | R5: 12 | S5: 13 | T5: 14 | U5: 15 | V5: 16 | W5: 17 | X5: 18 | Y5: 19 | Z5: 20 | AA5: 21 | AB5: 22 | AC5: 23 | AD5: 24 | AE5: 25 | AF5: 26 | AG5: 27 | AH5: 28 | AI5: 29 | AJ5: 30
A6: Fase | C6: =Supuestos!$C$14 -> 0.2 | D6: =Supuestos!$C$15 -> 0.3 | E6: =Supuestos!$C$16 -> 0.3 | F6: =Supuestos!$C$17 -> 0.2 | G6: =Supuestos!$C$18 -> 0.8 | H6: =Supuestos!$C$19 -> 0.9 | I6: 1 | J6: 1 | K6: 1 | L6: 1 | M6: 1 | N6: 1 | O6: 1 | P6: 1 | Q6: 1 | R6: 1 | S6: 1 | T6: 1 | U6: 1 | V6: 1 | W6: 1 | X6: 1 | Y6: 1 | Z6: 1 | AA6: 1 | AB6: 1 | AC6: 1 | AD6: 1 | AE6: 1 | AF6: 1 | AG6: 1 | AH6: 1 | AI6: 1 | AJ6: 1
A7: Inversión | C7: =-(Supuestos!$C$8+Supuestos!$C$13)*C6 -> -10729 | D7: =-(Supuestos!$C$8+Supuestos!$C$13)*D6 -> -16093.5 | E7: =-(Supuestos!$C$8+Supuestos!$C$13)*E6 -> -16093.5 | F7: =-(Supuestos!$C$8+Supuestos!$C$13)*F6 -> -10729 | G7: 0 | H7: 0 | I7: 0 | J7: 0 | K7: 0 | L7: 0 | M7: 0 | N7: 0 | O7: 0 | P7: 0 | Q7: 0 | R7: 0 | S7: 0 | T7: 0 | U7: 0 | V7: 0 | W7: 0 | X7: 0 | Y7: 0 | Z7: 0 | AA7: 0 | AB7: 0 | AC7: 0 | AD7: 0 | AE7: 0 | AF7: 0 | AG7: 0 | AH7: 0 | AI7: 0 | AJ7: 0
A8: Ingresos | C8: 0 | D8: 0 | E8: 0 | F8: 0 | G8: =Ingresos!$C$68*G6 -> 1998.6928 | H8: =Ingresos!$C$68*H6 -> 2248.5294 | I8: =Ingresos!$C$68*I6 -> 2498.366 | J8: =Ingresos!$C$68*J6 -> 2498.366 | K8: =Ingresos!$C$68*K6 -> 2498.366 | L8: =Ingresos!$C$68*L6 -> 2498.366 | M8: =Ingresos!$C$68*M6 -> 2498.366 | N8: =Ingresos!$C$68*N6 -> 2498.366 | ... AJ8: =Ingresos!$C$68*AJ6 -> 2498.366
A9: Costos de operación | C9: 0 | D9: 0 | E9: 0 | F9: 0 | G9: =-Costos_Operacion!$C$42 -> -1881.5695 | H9: =-Costos_Operacion!$C$42 -> -1881.5695 | I9: =-Costos_Operacion!$C$42 -> -1881.5695 | J9: =-Costos_Operacion!$C$42 -> -1881.5695 | K9: =-Costos_Operacion!$C$42 -> -1881.5695 | L9: =-Costos_Operacion!$C$42 -> -1881.5695 | M9: =-Costos_Operacion!$C$42 -> -1881.5695 | N9: =-Costos_Operacion!$C$42 -> -1881.5695 | ... AJ9: =-Costos_Operacion!$C$42 -> -1881.5695
A10: Energía extra por degradación de paneles | C10: 0 | D10: 0 | E10: 0 | F10: 0 | G10: =-Energia!$C$20*(1-(1-Supuestos!$C$146)^(1-1))*Supuestos!$C$153 -> 0 | H10: =-Energia!$C$20*(1-(1-Supuestos!$C$146)^(2-1))*Supuestos!$C$153 -> -0.21530673 | I10: =-Energia!$C$20*(1-(1-Supuestos!$C$146)^(3-1))*Supuestos!$C$153 -> -0.42953693 | J10: =-Energia!$C$20*(1-(1-Supuestos!$C$146)^(4-1))*Supuestos!$C$153 -> -0.64269597 | K10: =-Energia!$C$20*(1-(1-Supuestos!$C$146)^(5-1))*Supuestos!$C$153 -> -0.85478922 | L10: =-Energia!$C$20*(1-(1-Supuestos!$C$146)^(6-1))*Supuestos!$C$153 -> -1.065822 | M10: =-Energia!$C$20*(1-(1-Supuestos!$C$146)^(7-1))*Supuestos!$C$153 -> -1.2757996 | N10: =-Energia!$C$20*(1-(1-Supuestos!$C$146)^(8-1))*Supuestos!$C$153 -> -1.4847274 | O10: =-Energia!$C$20*(1-(1-Supuestos!$C$146)^(9-1))*Supuestos!$C$153 -> -1.6926104 | P10: =-Energia!$C$20*(1-(1-Supuestos!$C$146)^(10-1))*Supuestos!$C$153 -> -1.8994541 | Q10: =-Energia!$C$20*(1-(1-Supuestos!$C$146)^(11-1))*Supuestos!$C$153 -> -2.1052636 | R10: =-Energia!$C$20*(1-(1-Supuestos!$C$146)^(12-1))*Supuestos!$C$153 -> -2.310044 | S10: =-Energia!$C$20*(1-(1-Supuestos!$C$146)^(13-1))*Supuestos!$C$153 -> -2.5138005 | T10: =-Energia!$C$20*(1-(1-Supuestos!$C$146)^(14-1))*Supuestos!$C$153 -> -2.7165382 | U10: =-Energia!$C$20*(1-(1-Supuestos!$C$146)^(15-1))*Supuestos!$C$153 -> -2.9182623 | V10: =-Energia!$C$20*(1-(1-Supuestos!$C$146)^(16-1))*Supuestos!$C$153 -> -3.1189777 | W10: =-Energia!$C$20*(1-(1-Supuestos!$C$146)^(17-1))*Supuestos!$C$153 -> -3.3186895 | X10: =-Energia!$C$20*(1-(1-Supuestos!$C$146)^(18-1))*Supuestos!$C$153 -> -3.5174028 | Y10: =-Energia!$C$20*(1-(1-Supuestos!$C$146)^(19-1))*Supuestos!$C$153 -> -3.7151225 | Z10: =-Energia!$C$20*(1-(1-Supuestos!$C$146)^(20-1))*Supuestos!$C$153 -> -3.9118536 | AA10: =-Energia!$C$20*(1-(1-Supuestos!$C$146)^(21-1))*Supuestos!$C$153 -> -4.1076011 | AB10: =-Energia!$C$20*(1-(1-Supuestos!$C$146)^(22-1))*Supuestos!$C$153 -> -4.3023698 | AC10: =-Energia!$C$20*(1-(1-Supuestos!$C$146)^(23-1))*Supuestos!$C$153 -> -4.4961647 | AD10: =-Energia!$C$20*(1-(1-Supuestos!$C$146)^(24-1))*Supuestos!$C$153 -> -4.6889906 | AE10: =-Energia!$C$20*(1-(1-Supuestos!$C$146)^(25-1))*Supuestos!$C$153 -> -4.8808524 | AF10: =-Energia!$C$20*(1-(1-Supuestos!$C$146)^(26-1))*Supuestos!$C$153 -> -5.0717549 | AG10: =-Energia!$C$20*(1-(1-Supuestos!$C$146)^(27-1))*Supuestos!$C$153 -> -5.2617028 | AH10: =-Energia!$C$20*(1-(1-Supuestos!$C$146)^(28-1))*Supuestos!$C$153 -> -5.450701 | AI10: =-Energia!$C$20*(1-(1-Supuestos!$C$146)^(29-1))*Supuestos!$C$153 -> -5.6387543 | AJ10: =-Energia!$C$20*(1-(1-Supuestos!$C$146)^(30-1))*Supuestos!$C$153 -> -5.8258672
A11: EBITDA | C11: =C8+C9+C10 -> 0 | D11: =D8+D9+D10 -> 0 | E11: =E8+E9+E10 -> 0 | F11: =F8+F9+F10 -> 0 | G11: =G8+G9+G10 -> 117.12331 | H11: =H8+H9+H10 -> 366.7446 | I11: =I8+I9+I10 -> 616.36697 | J11: =J8+J9+J10 -> 616.15381 | ... AJ11: =AJ8+AJ9+AJ10 -> 610.97064
A12: Depreciación fiscal | C12: 0 | D12: 0 | E12: 0 | F12: 0 | G12: =IF(1<=1/Supuestos!$C$22,(Supuestos!$C$8)*Supuestos!$C$22,0) -> 2662.25 | H12: =IF(2<=1/Supuestos!$C$22,(Supuestos!$C$8)*Supuestos!$C$22,0) -> 2662.25 | I12: =IF(3<=1/Supuestos!$C$22,(Supuestos!$C$8)*Supuestos!$C$22,0) -> 2662.25 | J12: =IF(4<=1/Supuestos!$C$22,(Supuestos!$C$8)*Supuestos!$C$22,0) -> 2662.25 | K12: =IF(5<=1/Supuestos!$C$22,(Supuestos!$C$8)*Supuestos!$C$22,0) -> 2662.25 | L12: =IF(6<=1/Supuestos!$C$22,(Supuestos!$C$8)*Supuestos!$C$22,0) -> 2662.25 | M12: =IF(7<=1/Supuestos!$C$22,(Supuestos!$C$8)*Supuestos!$C$22,0) -> 2662.25 | N12: =IF(8<=1/Supuestos!$C$22,(Supuestos!$C$8)*Supuestos!$C$22,0) -> 2662.25 | O12: =IF(9<=1/Supuestos!$C$22,(Supuestos!$C$8)*Supuestos!$C$22,0) -> 2662.25 | P12: =IF(10<=1/Supuestos!$C$22,(Supuestos!$C$8)*Supuestos!$C$22,0) -> 2662.25 | Q12: =IF(11<=1/Supuestos!$C$22,(Supuestos!$C$8)*Supuestos!$C$22,0) -> 2662.25 | R12: =IF(12<=1/Supuestos!$C$22,(Supuestos!$C$8)*Supuestos!$C$22,0) -> 2662.25 | S12: =IF(13<=1/Supuestos!$C$22,(Supuestos!$C$8)*Supuestos!$C$22,0) -> 2662.25 | T12: =IF(14<=1/Supuestos!$C$22,(Supuestos!$C$8)*Supuestos!$C$22,0) -> 2662.25 | U12: =IF(15<=1/Supuestos!$C$22,(Supuestos!$C$8)*Supuestos!$C$22,0) -> 2662.25 | V12: =IF(16<=1/Supuestos!$C$22,(Supuestos!$C$8)*Supuestos!$C$22,0) -> 2662.25 | W12: =IF(17<=1/Supuestos!$C$22,(Supuestos!$C$8)*Supuestos!$C$22,0) -> 2662.25 | X12: =IF(18<=1/Supuestos!$C$22,(Supuestos!$C$8)*Supuestos!$C$22,0) -> 2662.25 | Y12: =IF(19<=1/Supuestos!$C$22,(Supuestos!$C$8)*Supuestos!$C$22,0) -> 2662.25 | Z12: =IF(20<=1/Supuestos!$C$22,(Supuestos!$C$8)*Supuestos!$C$22,0) -> 2662.25 | AA12: =IF(21<=1/Supuestos!$C$22,(Supuestos!$C$8)*Supuestos!$C$22,0) -> 0 | AB12: =IF(22<=1/Supuestos!$C$22,(Supuestos!$C$8)*Supuestos!$C$22,0) -> 0 | AC12: =IF(23<=1/Supuestos!$C$22,(Supuestos!$C$8)*Supuestos!$C$22,0) -> 0 | AD12: =IF(24<=1/Supuestos!$C$22,(Supuestos!$C$8)*Supuestos!$C$22,0) -> 0 | AE12: =IF(25<=1/Supuestos!$C$22,(Supuestos!$C$8)*Supuestos!$C$22,0) -> 0 | AF12: =IF(26<=1/Supuestos!$C$22,(Supuestos!$C$8)*Supuestos!$C$22,0) -> 0 | AG12: =IF(27<=1/Supuestos!$C$22,(Supuestos!$C$8)*Supuestos!$C$22,0) -> 0 | AH12: =IF(28<=1/Supuestos!$C$22,(Supuestos!$C$8)*Supuestos!$C$22,0) -> 0 | AI12: =IF(29<=1/Supuestos!$C$22,(Supuestos!$C$8)*Supuestos!$C$22,0) -> 0 | AJ12: =IF(30<=1/Supuestos!$C$22,(Supuestos!$C$8)*Supuestos!$C$22,0) -> 0
A13: ISR | C13: =-MAX(0,C11-C12)*Supuestos!$C$21 -> 0 | D13: =-MAX(0,D11-D12)*Supuestos!$C$21 -> 0 | E13: =-MAX(0,E11-E12)*Supuestos!$C$21 -> 0 | F13: =-MAX(0,F11-F12)*Supuestos!$C$21 -> 0 | G13: =-MAX(0,G11-G12)*Supuestos!$C$21 -> 0 | H13: =-MAX(0,H11-H12)*Supuestos!$C$21 -> 0 | I13: =-MAX(0,I11-I12)*Supuestos!$C$21 -> 0 | J13: =-MAX(0,J11-J12)*Supuestos!$C$21 -> 0 | ... AJ13: =-MAX(0,AJ11-AJ12)*Supuestos!$C$21 -> -183.29119
A14: Flujo antes de impuestos | C14: =C7+C11 -> -10729 | D14: =D7+D11 -> -16093.5 | E14: =E7+E11 -> -16093.5 | F14: =F7+F11 -> -10729 | G14: =G7+G11 -> 117.12331 | H14: =H7+H11 -> 366.7446 | I14: =I7+I11 -> 616.36697 | J14: =J7+J11 -> 616.15381 | ... AJ14: =AJ7+AJ11 -> 610.97064
A15: Flujo después de impuestos | C15: =C14+C13 -> -10729 | D15: =D14+D13 -> -16093.5 | E15: =E14+E13 -> -16093.5 | F15: =F14+F13 -> -10729 | G15: =G14+G13 -> 117.12331 | H15: =H14+H13 -> 366.7446 | I15: =I14+I13 -> 616.36697 | J15: =J14+J13 -> 616.15381 | ... AJ15: =AJ14+AJ13 -> 427.67945
A16: Acumulado | C16: =C15 -> -10729 | D16: =C16+D15 -> -26822.5 | E16: =D16+E15 -> -42916 | F16: =E16+F15 -> -53645 | G16: =F16+G15 -> -53527.877 | H16: =G16+H15 -> -53161.132 | I16: =H16+I15 -> -52544.765 | J16: =I16+J15 -> -51928.611 | K16: =J16+K15 -> -51312.67 | ... AJ16: =AI16+AJ15 -> -37815.518
A17: Flujo descontado | C17: =C15/(1+Supuestos!$C$20)^0 -> -10729 | D17: =D15/(1+Supuestos!$C$20)^1 -> -14764.679 | E17: =E15/(1+Supuestos!$C$20)^2 -> -13545.577 | F17: =F15/(1+Supuestos!$C$20)^3 -> -8284.7566 | G17: =G15/(1+Supuestos!$C$20)^4 -> 82.973104 | H17: =H15/(1+Supuestos!$C$20)^5 -> 238.35883 | I17: =I15/(1+Supuestos!$C$20)^6 -> 367.51949 | J17: =J15/(1+Supuestos!$C$20)^7 -> 337.05724 | K17: =K15/(1+Supuestos!$C$20)^8 -> 309.12038 | L17: =L15/(1+Supuestos!$C$20)^9 -> 283.49951 | M17: =M15/(1+Supuestos!$C$20)^10 -> 260.0026 | N17: =N15/(1+Supuestos!$C$20)^11 -> 238.45353 | O17: =O15/(1+Supuestos!$C$20)^12 -> 218.6908 | P17: =P15/(1+Supuestos!$C$20)^13 -> 200.56629 | Q17: =Q15/(1+Supuestos!$C$20)^14 -> 183.94418 | R17: =R15/(1+Supuestos!$C$20)^15 -> 168.69991 | S17: =S15/(1+Supuestos!$C$20)^16 -> 154.71924 | T17: =T15/(1+Supuestos!$C$20)^17 -> 141.89741 | U17: =U15/(1+Supuestos!$C$20)^18 -> 130.13835 | V17: =V15/(1+Supuestos!$C$20)^19 -> 119.35394 | W17: =W15/(1+Supuestos!$C$20)^20 -> 109.46339 | X17: =X15/(1+Supuestos!$C$20)^21 -> 100.3926 | Y17: =Y15/(1+Supuestos!$C$20)^22 -> 92.073611 | Z17: =Z15/(1+Supuestos!$C$20)^23 -> 84.444097 | AA17: =AA15/(1+Supuestos!$C$20)^24 -> 54.212834 | AB17: =AB15/(1+Supuestos!$C$20)^25 -> 49.720734 | AC17: =AC15/(1+Supuestos!$C$20)^26 -> 45.600919 | AD17: =AD15/(1+Supuestos!$C$20)^27 -> 41.822531 | AE17: =AE15/(1+Supuestos!$C$20)^28 -> 38.357268 | AF17: =AF15/(1+Supuestos!$C$20)^29 -> 35.179175 | AG17: =AG15/(1+Supuestos!$C$20)^30 -> 32.264451 | AH17: =AH15/(1+Supuestos!$C$20)^31 -> 29.591266 | AI17: =AI15/(1+Supuestos!$C$20)^32 -> 27.139599 | AJ17: =AJ15/(1+Supuestos!$C$20)^33 -> 24.891092
A18: Acumulado descontado | C18: =C17 -> -10729 | D18: =C18+D17 -> -25493.679 | E18: =D18+E17 -> -39039.256 | F18: =E18+F17 -> -47324.012 | G18: =F18+G17 -> -47241.039 | H18: =G18+H17 -> -47002.68 | I18: =H18+I17 -> -46635.161 | J18: =I18+J17 -> -46298.104 | K18: =J18+K17 -> -45988.983 | ... AJ18: =AI18+AJ17 -> -43123.864
A19: VPN a la tasa real (después de impuestos) | B19: =SUM(C17:AJ17) -> -43123.864
A20: TIR real antes de impuestos | B20: =IFERROR(IRR(C14:AJ14,0.02),IFERROR(IRR(C14:AJ14,-0.05),"negativa")) -> -0.055436918
A21: TIR real después de impuestos | B21: =IFERROR(IRR(C15:AJ15,0.02),IFERROR(IRR(C15:AJ15,-0.05),"negativa")) -> -0.063561192
A22: Recuperación (años desde la apertura) | B22: =IF(COUNTIF(G16:AJ16,"<0")>=30,"más de 30",COUNTIF(G16:AJ16,"<0")+1) -> más de 30
A23: Recuperación descontada (años desde la apertura) | B23: =IF(COUNTIF(G18:AJ18,"<0")>=30,"más de 30",COUNTIF(G18:AJ18,"<0")+1) -> más de 30
A24: Efectivo acumulado al año 30 | B24: =AJ16 -> -37815.518
A27: Escenario Base
A28: Año | C28: Obra 1 | D28: Obra 2 | E28: Obra 3 | F28: Obra 4 | G28: 1 | H28: 2 | I28: 3 | J28: 4 | K28: 5 | L28: 6 | M28: 7 | N28: 8 | O28: 9 | P28: 10 | Q28: 11 | R28: 12 | S28: 13 | T28: 14 | U28: 15 | V28: 16 | W28: 17 | X28: 18 | Y28: 19 | Z28: 20 | AA28: 21 | AB28: 22 | AC28: 23 | AD28: 24 | AE28: 25 | AF28: 26 | AG28: 27 | AH28: 28 | AI28: 29 | AJ28: 30
A29: Fase | C29: =Supuestos!$D$14 -> 0.2 | D29: =Supuestos!$D$15 -> 0.3 | E29: =Supuestos!$D$16 -> 0.3 | F29: =Supuestos!$D$17 -> 0.2 | G29: =Supuestos!$D$18 -> 0.85 | H29: =Supuestos!$D$19 -> 0.95 | I29: 1 | J29: 1 | K29: 1 | L29: 1 | M29: 1 | N29: 1 | O29: 1 | P29: 1 | Q29: 1 | R29: 1 | S29: 1 | T29: 1 | U29: 1 | V29: 1 | W29: 1 | X29: 1 | Y29: 1 | Z29: 1 | AA29: 1 | AB29: 1 | AC29: 1 | AD29: 1 | AE29: 1 | AF29: 1 | AG29: 1 | AH29: 1 | AI29: 1 | AJ29: 1
A30: Inversión | C30: =-(Supuestos!$D$8+Supuestos!$D$13)*C29 -> -10709 | D30: =-(Supuestos!$D$8+Supuestos!$D$13)*D29 -> -16063.5 | E30: =-(Supuestos!$D$8+Supuestos!$D$13)*E29 -> -16063.5 | F30: =-(Supuestos!$D$8+Supuestos!$D$13)*F29 -> -10709 | G30: 0 | H30: 0 | I30: 0 | J30: 0 | K30: 0 | L30: 0 | M30: 0 | N30: 0 | O30: 0 | P30: 0 | Q30: 0 | R30: 0 | S30: 0 | T30: 0 | U30: 0 | V30: 0 | W30: 0 | X30: 0 | Y30: 0 | Z30: 0 | AA30: 0 | AB30: 0 | AC30: 0 | AD30: 0 | AE30: 0 | AF30: 0 | AG30: 0 | AH30: 0 | AI30: 0 | AJ30: 0
A31: Ingresos | C31: 0 | D31: 0 | E31: 0 | F31: 0 | G31: =Ingresos!$D$68*G29 -> 3796.4719 | H31: =Ingresos!$D$68*H29 -> 4243.1156 | I31: =Ingresos!$D$68*I29 -> 4466.4375 | J31: =Ingresos!$D$68*J29 -> 4466.4375 | K31: =Ingresos!$D$68*K29 -> 4466.4375 | L31: =Ingresos!$D$68*L29 -> 4466.4375 | M31: =Ingresos!$D$68*M29 -> 4466.4375 | N31: =Ingresos!$D$68*N29 -> 4466.4375 | ... AJ31: =Ingresos!$D$68*AJ29 -> 4466.4375
A32: Costos de operación | C32: 0 | D32: 0 | E32: 0 | F32: 0 | G32: =-Costos_Operacion!$D$42 -> -1718.0966 | H32: =-Costos_Operacion!$D$42 -> -1718.0966 | I32: =-Costos_Operacion!$D$42 -> -1718.0966 | J32: =-Costos_Operacion!$D$42 -> -1718.0966 | K32: =-Costos_Operacion!$D$42 -> -1718.0966 | L32: =-Costos_Operacion!$D$42 -> -1718.0966 | M32: =-Costos_Operacion!$D$42 -> -1718.0966 | N32: =-Costos_Operacion!$D$42 -> -1718.0966 | ... AJ32: =-Costos_Operacion!$D$42 -> -1718.0966
