Workbook

Sheet Resumen
A1: ESTADIO YAXCHÉ + PLAZA SAKBÉ — Resumen del costo de construcción
A2: MXN sin IVA salvo donde se indica. Estimado de concepto ±25 %. Excluye terreno, mobiliario de locatarios y costos financieros.
A4: Capítulo | B4: Estadio | C4: Plaza Sakbé | D4: Subterráneo y obra común | E4: Total (MXN) | F4: % del directo
A5: 01 Preliminares y obras provisionales | B5: =SUMIFS(Presupuesto!$H$5:$H$231,Presupuesto!$A$5:$A$231,$A5,Presupuesto!$B$5:$B$231,"Estadio") -> 0 | C5: =SUMIFS(Presupuesto!$H$5:$H$231,Presupuesto!$A$5:$A$231,$A5,Presupuesto!$B$5:$B$231,"Plaza Sakbé") -> 0 | D5: =SUMIFS(Presupuesto!$H$5:$H$231,Presupuesto!$A$5:$A$231,$A5,Presupuesto!$B$5:$B$231,"Subterráneo y obra común") -> 1.114515e+09 | E5: =SUM(B5:D5) -> 1.114515e+09 | F5: =IF($E$23=0,0,E5/$E$23) -> 0.029932244
A6: 02 Excavación, contención y cimentación | B6: =SUMIFS(Presupuesto!$H$5:$H$231,Presupuesto!$A$5:$A$231,$A6,Presupuesto!$B$5:$B$231,"Estadio") -> 44185759 | C6: =SUMIFS(Presupuesto!$H$5:$H$231,Presupuesto!$A$5:$A$231,$A6,Presupuesto!$B$5:$B$231,"Plaza Sakbé") -> 0 | D6: =SUMIFS(Presupuesto!$H$5:$H$231,Presupuesto!$A$5:$A$231,$A6,Presupuesto!$B$5:$B$231,"Subterráneo y obra común") -> 3.5216054e+09 | E6: =SUM(B6:D6) -> 3.5657912e+09 | F6: =IF($E$23=0,0,E6/$E$23) -> 0.095765538
A7: 03 Estructura de concreto | B7: =SUMIFS(Presupuesto!$H$5:$H$231,Presupuesto!$A$5:$A$231,$A7,Presupuesto!$B$5:$B$231,"Estadio") -> 1.4841561e+09 | C7: =SUMIFS(Presupuesto!$H$5:$H$231,Presupuesto!$A$5:$A$231,$A7,Presupuesto!$B$5:$B$231,"Plaza Sakbé") -> 2.0403807e+09 | D7: =SUMIFS(Presupuesto!$H$5:$H$231,Presupuesto!$A$5:$A$231,$A7,Presupuesto!$B$5:$B$231,"Subterráneo y obra común") -> 2.1780737e+09 | E7: =SUM(B7:D7) -> 5.7026105e+09 | F7: =IF($E$23=0,0,E7/$E$23) -> 0.15315354
A8: 04 Estructura metálica y de madera | B8: =SUMIFS(Presupuesto!$H$5:$H$231,Presupuesto!$A$5:$A$231,$A8,Presupuesto!$B$5:$B$231,"Estadio") -> 9.4728358e+08 | C8: =SUMIFS(Presupuesto!$H$5:$H$231,Presupuesto!$A$5:$A$231,$A8,Presupuesto!$B$5:$B$231,"Plaza Sakbé") -> 5.3193646e+08 | D8: =SUMIFS(Presupuesto!$H$5:$H$231,Presupuesto!$A$5:$A$231,$A8,Presupuesto!$B$5:$B$231,"Subterráneo y obra común") -> 0 | E8: =SUM(B8:D8) -> 1.47922e+09 | F8: =IF($E$23=0,0,E8/$E$23) -> 0.039727032
A9: 05 Cubiertas (fija y retráctil) | B9: =SUMIFS(Presupuesto!$H$5:$H$231,Presupuesto!$A$5:$A$231,$A9,Presupuesto!$B$5:$B$231,"Estadio") -> 3.8734542e+09 | C9: =SUMIFS(Presupuesto!$H$5:$H$231,Presupuesto!$A$5:$A$231,$A9,Presupuesto!$B$5:$B$231,"Plaza Sakbé") -> 0 | D9: =SUMIFS(Presupuesto!$H$5:$H$231,Presupuesto!$A$5:$A$231,$A9,Presupuesto!$B$5:$B$231,"Subterráneo y obra común") -> 0 | E9: =SUM(B9:D9) -> 3.8734542e+09 | F9: =IF($E$23=0,0,E9/$E$23) -> 0.10402836
A10: 06 Fachadas y vidrios | B10: =SUMIFS(Presupuesto!$H$5:$H$231,Presupuesto!$A$5:$A$231,$A10,Presupuesto!$B$5:$B$231,"Estadio") -> 1.7490564e+09 | C10: =SUMIFS(Presupuesto!$H$5:$H$231,Presupuesto!$A$5:$A$231,$A10,Presupuesto!$B$5:$B$231,"Plaza Sakbé") -> 3342858787 | D10: =SUMIFS(Presupuesto!$H$5:$H$231,Presupuesto!$A$5:$A$231,$A10,Presupuesto!$B$5:$B$231,"Subterráneo y obra común") -> 0 | E10: =SUM(B10:D10) -> 5.0919152e+09 | F10: =IF($E$23=0,0,E10/$E$23) -> 0.13675226
A11: 07 Albañilería, acabados y carpintería | B11: =SUMIFS(Presupuesto!$H$5:$H$231,Presupuesto!$A$5:$A$231,$A11,Presupuesto!$B$5:$B$231,"Estadio") -> 1.6084087e+09 | C11: =SUMIFS(Presupuesto!$H$5:$H$231,Presupuesto!$A$5:$A$231,$A11,Presupuesto!$B$5:$B$231,"Plaza Sakbé") -> 2.2313884e+09 | D11: =SUMIFS(Presupuesto!$H$5:$H$231,Presupuesto!$A$5:$A$231,$A11,Presupuesto!$B$5:$B$231,"Subterráneo y obra común") -> 4.3102878e+08 | E11: =SUM(B11:D11) -> 4.2708259e+09 | F11: =IF($E$23=0,0,E11/$E$23) -> 0.11470047
A12: 08 Instalación eléctrica, iluminación y energía | B12: =SUMIFS(Presupuesto!$H$5:$H$231,Presupuesto!$A$5:$A$231,$A12,Presupuesto!$B$5:$B$231,"Estadio") -> 970110710 | C12: =SUMIFS(Presupuesto!$H$5:$H$231,Presupuesto!$A$5:$A$231,$A12,Presupuesto!$B$5:$B$231,"Plaza Sakbé") -> 846349030 | D12: =SUMIFS(Presupuesto!$H$5:$H$231,Presupuesto!$A$5:$A$231,$A12,Presupuesto!$B$5:$B$231,"Subterráneo y obra común") -> 952408000 | E12: =SUM(B12:D12) -> 2768867740 | F12: =IF($E$23=0,0,E12/$E$23) -> 0.074362769
A13: 09 Instalaciones hidráulicas, sanitarias y pluviales | B13: =SUMIFS(Presupuesto!$H$5:$H$231,Presupuesto!$A$5:$A$231,$A13,Presupuesto!$B$5:$B$231,"Estadio") -> 198959177 | C13: =SUMIFS(Presupuesto!$H$5:$H$231,Presupuesto!$A$5:$A$231,$A13,Presupuesto!$B$5:$B$231,"Plaza Sakbé") -> 366779857 | D13: =SUMIFS(Presupuesto!$H$5:$H$231,Presupuesto!$A$5:$A$231,$A13,Presupuesto!$B$5:$B$231,"Subterráneo y obra común") -> 369528243 | E13: =SUM(B13:D13) -> 935267277 | F13: =IF($E$23=0,0,E13/$E$23) -> 0.025118233
A14: 10 Climatización y ventilación | B14: =SUMIFS(Presupuesto!$H$5:$H$231,Presupuesto!$A$5:$A$231,$A14,Presupuesto!$B$5:$B$231,"Estadio") -> 2.9584365e+08 | C14: =SUMIFS(Presupuesto!$H$5:$H$231,Presupuesto!$A$5:$A$231,$A14,Presupuesto!$B$5:$B$231,"Plaza Sakbé") -> 1003818556 | D14: =SUMIFS(Presupuesto!$H$5:$H$231,Presupuesto!$A$5:$A$231,$A14,Presupuesto!$B$5:$B$231,"Subterráneo y obra común") -> 7.8259142e+08 | E14: =SUM(B14:D14) -> 2.0822536e+09 | F14: =IF($E$23=0,0,E14/$E$23) -> 0.05592255
A15: 11 Protección contra incendio y seguridad humana | B15: =SUMIFS(Presupuesto!$H$5:$H$231,Presupuesto!$A$5:$A$231,$A15,Presupuesto!$B$5:$B$231,"Estadio") -> 0 | C15: =SUMIFS(Presupuesto!$H$5:$H$231,Presupuesto!$A$5:$A$231,$A15,Presupuesto!$B$5:$B$231,"Plaza Sakbé") -> 0 | D15: =SUMIFS(Presupuesto!$H$5:$H$231,Presupuesto!$A$5:$A$231,$A15,Presupuesto!$B$5:$B$231,"Subterráneo y obra común") -> 1.021933e+09 | E15: =SUM(B15:D15) -> 1.021933e+09 | F15: =IF($E$23=0,0,E15/$E$23) -> 0.027445792
A16: 12 Voz y datos, seguridad y sistemas especiales | B16: =SUMIFS(Presupuesto!$H$5:$H$231,Presupuesto!$A$5:$A$231,$A16,Presupuesto!$B$5:$B$231,"Estadio") -> 521200000 | C16: =SUMIFS(Presupuesto!$H$5:$H$231,Presupuesto!$A$5:$A$231,$A16,Presupuesto!$B$5:$B$231,"Plaza Sakbé") -> 0 | D16: =SUMIFS(Presupuesto!$H$5:$H$231,Presupuesto!$A$5:$A$231,$A16,Presupuesto!$B$5:$B$231,"Subterráneo y obra común") -> 6.7072786e+08 | E16: =SUM(B16:D16) -> 1.1919279e+09 | F16: =IF($E$23=0,0,E16/$E$23) -> 0.0320113
... A22: 18 Pruebas, puesta en marcha y certificaciones | B22: =SUMIFS(Presupuesto!$H$5:$H$231,Presupuesto!$A$5:$A$231,$A22,Presupuesto!$B$5:$B$231,"Estadio") -> 22000000 | C22: =SUMIFS(Presupuesto!$H$5:$H$231,Presupuesto!$A$5:$A$231,$A22,Presupuesto!$B$5:$B$231,"Plaza Sakbé") -> 0 | D22: =SUMIFS(Presupuesto!$H$5:$H$231,Presupuesto!$A$5:$A$231,$A22,Presupuesto!$B$5:$B$231,"Subterráneo y obra común") -> 274400000 | E22: =SUM(B22:D22) -> 296400000 | F22: =IF($E$23=0,0,E22/$E$23) -> 0.0079603386
A23: COSTO DIRECTO | B23: =SUM(B5:B22) -> 1.2401226e+10 | C23: =SUM(C5:C22) -> 1.202513e+10 | D23: =SUM(D5:D22) -> 1.280824e+10 | E23: =SUM(E5:E22) -> 3.7234597e+10
A25: Indirectos de obra | E25: =$E$23*F25 -> 4.4681516e+09 | F25: =Supuestos!$C$5 -> 0.12
A26: Utilidad del contratista | E26: =$E$23*F26 -> 2.9787678e+09 | F26: =Supuestos!$C$6 -> 0.08
A27: Proyecto ejecutivo e ingenierías | E27: =$E$23*F27 -> 2.2340758e+09 | F27: =Supuestos!$C$7 -> 0.06
A28: Licencias, permisos, DRO | E28: =$E$23*F28 -> 5.5851896e+08 | F28: =Supuestos!$C$8 -> 0.015
A29: Supervisión y gerencia | E29: =$E$23*F29 -> 9.3086493e+08 | F29: =Supuestos!$C$9 -> 0.025
A30: Subtotal antes de contingencia | E30: =E23+SUM(E25:E29) -> 4.8404976e+10
A31: Contingencia | E31: =E30*F31 -> 4.8404976e+09 | F31: =Supuestos!$C$10 -> 0.1
A32: TOTAL SIN IVA | E32: =E30+E31 -> 5.3245474e+10
A33: IVA | E33: =E32*F33 -> 8.5192758e+09 | F33: =Supuestos!$C$11 -> 0.16
A34: TOTAL CON IVA (MXN) | E34: =E32+E33 -> 6.176475e+10
A35: TOTAL CON IVA (USD) | E35: =E34/Supuestos!$C$4 -> 3.3386351e+09
A37: Indicadores
A38: Estadio: costo total sin IVA (MXN) | E38: =B23*(E32/E23) -> 1.7733754e+10
A39: Estadio: costo por butaca (MXN) | E39: =B23*(E32/E23)/Cantidades_Modelo!$C$56 -> 176826.51
A40: Estadio: costo por butaca (USD) | E40: =B23*(E32/E23)/Cantidades_Modelo!$C$56/Supuestos!$C$4 -> 9558.1896
A41: Plaza Sakbé: costo total sin IVA (MXN) | E41: =C23*(E32/E23) -> 1.7195936e+10
A42: Plaza Sakbé: costo por m² construido (MXN) | E42: =C23*(E32/E23)/Cantidades_Modelo!$C$26 -> 44539.358
A43: Subterráneo y obra común: costo sin IVA (MXN) | E43: =D23*(E32/E23) -> 1.8315784e+10
A44: Estacionamiento + obra común por cajón (MXN) | E44: =D23*(E32/E23)/Cantidades_Modelo!$C$57 -> 3220074.5
A46: Notas: costo indirecto, utilidad y contingencia se reparten en proporción al directo en los indicadores. No incluye terreno, demoliciones fuera del predio, obras viales externas, mobiliario/equipo de locatarios ni costo financiero.

Sheet Presupuesto
A1: Estadio Yaxché + Plaza Sakbé — Presupuesto paramétrico de construcción (MXN, sin IVA)
A2: Estimado de concepto (clase 4, ±25 %). Precios unitarios de mercado en México 2025–2026, incluyen material, mano de obra, equipo y desperdicio; verificar con cotizaciones.
A4: Capítulo | B4: Zona | C4: Clave | D4: Concepto | E4: Unidad | F4: Cantidad | G4: P.U. (MXN) | H4: Importe (MXN) | I4: Material / insumo | J4: Criterio de cantidad
A5: 01 Preliminares y obras provisionales
A6: 01 Preliminares y obras provisionales | B6: Subterráneo y obra común | C6: 01.01 | D6: Limpieza, despalme y trazo/nivelación del predio | E6: m² | F6: =Cantidades_Modelo!$C$4 -> 283535.79 | G6: 38 | H6: =F6*G6 -> 10774360 | I6: Mano de obra y topografía | J6: Medido del modelo / factor en Supuestos
A7: 01 Preliminares y obras provisionales | B7: Subterráneo y obra común | C7: 01.02 | D7: Tapial / cerca perimetral de obra | E7: m | F7: =Cantidades_Modelo!$C$7 -> 1900.26 | G7: 2600 | H7: =F7*G7 -> 4940676 | I7: Lámina y postes de acero | J7: Medido del modelo / factor en Supuestos
A8: 01 Preliminares y obras provisionales | B8: Subterráneo y obra común | C8: 01.03 | D8: Oficinas, bodegas, comedor y sanitarios de obra | E8: mes | F8: =Supuestos!$C$12 -> 48 | G8: 1450000 | H8: =F8*G8 -> 69600000 | I8: Renta de instalaciones provisionales | J8: Medido del modelo / factor en Supuestos
A9: 01 Preliminares y obras provisionales | B9: Subterráneo y obra común | C9: 01.04 | D9: Energía, agua y drenaje provisionales | E9: mes | F9: =Supuestos!$C$12 -> 48 | G9: 850000 | H9: =F9*G9 -> 40800000 | I9: Servicios provisionales | J9: Medido del modelo / factor en Supuestos
A10: 01 Preliminares y obras provisionales | B10: Subterráneo y obra común | C10: 01.05 | D10: Grúas torre (6) y grúa de celosía para cubierta (renta, montaje, operador) | E10: mes | F10: =Supuestos!$C$12 -> 48 | G10: 9800000 | H10: =F10*G10 -> 470400000 | I10: Renta de grúas | J10: Medido del modelo / factor en Supuestos
A11: 01 Preliminares y obras provisionales | B11: Subterráneo y obra común | C11: 01.06 | D11: Seguridad, vigilancia, señalización y protección civil de obra | E11: mes | F11: =Supuestos!$C$12 -> 48 | G11: 1250000 | H11: =F11*G11 -> 60000000 | I11: Servicios de seguridad | J11: Medido del modelo / factor en Supuestos
A12: 01 Preliminares y obras provisionales | B12: Subterráneo y obra común | C12: 01.07 | D12: Estudios: mecánica de suelos, topografía, geofísica, impacto ambiental y vial | E12: lote | F12: 1 | G12: 38000000 | H12: =F12*G12 -> 38000000 | I12: Estudios técnicos | J12: Lote / cantidad de diseño
A13: 01 Preliminares y obras provisionales | B13: Subterráneo y obra común | C13: 01.08 | D13: Fianzas y seguros de obra (todo riesgo construcción) | E13: lote | F13: 1 | G13: 420000000 | H13: =F13*G13 -> 420000000 | I13: Seguros y fianzas | J13: Lote / cantidad de diseño
A14: 02 Excavación, contención y cimentación
A15: 02 Excavación, contención y cimentación | B15: Subterráneo y obra común | C15: 02.01 | D15: Muro Milán (pantalla) de concreto armado, e = 0.80 m, incl. lodos bentoníticos | E15: m² | F15: =Cantidades_Modelo!$C$6*Supuestos!$C$15 -> 30717.54 | G15: 11800 | H15: =F15*G15 -> 362466972 | I15: Concreto f'c 350 + acero + lodo bentonítico | J15: Medido del modelo / factor en Supuestos
A16: 02 Excavación, contención y cimentación | B16: Subterráneo y obra común | C16: 02.02 | D16: Excavación masiva en caja a 13 m con equipo mecánico | E16: m³ | F16: =Cantidades_Modelo!$C$5*Supuestos!$C$14 -> 2971508.1 | G16: 165 | H16: =F16*G16 -> 4.9029884e+08 | I16: Maquinaria y operación | J16: Medido del modelo / factor en Supuestos
A17: 02 Excavación, contención y cimentación | B17: Subterráneo y obra común | C17: 02.03 | D17: Carga y acarreo de material excavado a tiro autorizado (20 km) | E17: m³ | F17: =$F$16*Supuestos!$C$13 -> 3714385.2 | G17: 145 | H17: =F17*G17 -> 5.3858585e+08 | I17: Acarreo en camión | J17: Medido del modelo / factor en Supuestos
A18: 02 Excavación, contención y cimentación | B18: Subterráneo y obra común | C18: 02.04 | D18: Abatimiento del nivel freático (pozos y bombeo) | E18: mes | F18: 18 | G18: 1600000 | H18: =F18*G18 -> 28800000 | I18: Equipo de bombeo | J18: Lote / cantidad de diseño
A19: 02 Excavación, contención y cimentación | B19: Subterráneo y obra común | C19: 02.05 | D19: Anclas de muro Milán (3 niveles, @ 3 m) | E19: pza | F19: =Cantidades_Modelo!$C$6/3*3 -> 1706.53 | G19: 38000 | H19: =F19*G19 -> 64848140 | I19: Torón y lechada | J19: Medido del modelo / factor en Supuestos
A20: 02 Excavación, contención y cimentación | B20: Subterráneo y obra común | C20: 02.06 | D20: Pilas de cimentación Ø1.20 m, coladas en sitio | E20: m | F20: =Supuestos!$C$18*Supuestos!$C$19 -> 32275 | G20: 13500 | H20: =F20*G20 -> 435712500 | I20: Concreto f'c 300 + acero | J20: Medido del modelo / factor en Supuestos
A21: 02 Excavación, contención y cimentación | B21: Subterráneo y obra común | C21: 02.07 | D21: Plantilla de concreto f'c 100, e = 5 cm | E21: m² | F21: =Cantidades_Modelo!$C$5 -> 228577.55 | G21: 190 | H21: =F21*G21 -> 43429734 | I21: Concreto f'c 100 | J21: Medido del modelo / factor en Supuestos
A22: 02 Excavación, contención y cimentación | B22: Subterráneo y obra común | C22: 02.08 | D22: Losa de cimentación: concreto f'c 350 premezclado, bombeado | E22: m³ | F22: =Cantidades_Modelo!$C$5*Supuestos!$C$17 -> 205719.8 | G22: 3350 | H22: =F22*G22 -> 6.8916131e+08 | I22: Concreto f'c 350 | J22: Medido del modelo / factor en Supuestos
A23: 02 Excavación, contención y cimentación | B23: Subterráneo y obra común | C23: 02.09 | D23: Losa de cimentación: acero de refuerzo fy 4200 habilitado y colocado | E23: kg | F23: =$F$22*Supuestos!$C$33 -> 19543381 | G23: 31 | H23: =F23*G23 -> 6.058448e+08 | I23: Varilla corrugada fy 4200 | J23: Medido del modelo / factor en Supuestos
A24: 02 Excavación, contención y cimentación | B24: Subterráneo y obra común | C24: 02.10 | D24: Impermeabilización de cimentación y muros (membrana bentonítica) | E24: m² | F24: =Cantidades_Modelo!$C$5+$F$15 -> 259295.09 | G24: 520 | H24: =F24*G24 -> 1.3483345e+08 | I24: Membrana bentonítica | J24: Medido del modelo / factor en Supuestos
A25: 02 Excavación, contención y cimentación | B25: Subterráneo y obra común | C25: 02.11 | D25: Impermeabilización de losa de plaza bajo jardines (membrana antirraíz + protección) | E25: m² | F25: =Cantidades_Modelo!$C$19 -> 150227.88 | G25: 820 | H25: =F25*G25 -> 1.2318686e+08 | I25: Membrana antirraíz | J25: Medido del modelo / factor en Supuestos
A26: 02 Excavación, contención y cimentación | B26: Subterráneo y obra común | C26: 02.12 | D26: Juntas de colado con banda de PVC | E26: m | F26: =Cantidades_Modelo!$C$6*4 -> 6826.12 | G26: 650 | H26: =F26*G26 -> 4436978 | I26: Banda de PVC | J26: Medido del modelo / factor en Supuestos
A27: 02 Excavación, contención y cimentación | B27: Estadio | C27: 02.13 | D27: Relleno compactado bajo grada 1 (material de banco al 95 % Proctor) | E27: m³ | F27: =Cantidades_Modelo!$C$8*5.5 -> 92053.665 | G27: 480 | H27: =F27*G27 -> 44185759 | I27: Material de banco | J27: Medido del modelo / factor en Supuestos
A28: 03 Estructura de concreto
A29: 03 Estructura de concreto | B29: Estadio | C29: 03.01 | D29: Grada 1: losa escalonada f'c 350 sobre relleno | E29: m³ | F29: =Cantidades_Modelo!$C$8*Supuestos!$C$22*Supuestos!$C$20 -> 4811.8961 | G29: 3600 | H29: =F29*G29 -> 17322826 | I29: Concreto f'c 350 | J29: Medido del modelo / factor en Supuestos
A30: 03 Estructura de concreto | B30: Estadio | C30: 03.02 | D30: Gradas 2 y 3: elementos prefabricados y trabes inclinadas f'c 450 | E30: m³ | F30: =(Cantidades_Modelo!$C$9+Cantidades_Modelo!$C$10)*Supuestos!$C$22*Supuestos!$C$21 -> 30155.823 | G30: 7800 | H30: =F30*G30 -> 2.3521542e+08 | I30: Concreto prefabricado f'c 450 | J30: Medido del modelo / factor en Supuestos
A31: 03 Estructura de concreto | B31: Estadio | C31: 03.03 | D31: Marcos y trabes portantes de gradas 2 y 3 (f'c 450) | E31: m³ | F31: =(Cantidades_Modelo!$C$9+Cantidades_Modelo!$C$10)*0.35 -> 16687.017 | G31: 4300 | H31: =F31*G31 -> 71754171 | I31: Concreto f'c 450 | J31: Medido del modelo / factor en Supuestos
A32: 03 Estructura de concreto | B32: Estadio | C32: 03.04 | D32: Gradas: acero de refuerzo | E32: kg | F32: =($F$29+$F$30+$F$31)*Supuestos!$C$38 -> 7748210.3 | G32: 31 | H32: =F32*G32 -> 2.4019452e+08 | I32: Varilla corrugada fy 4200 | J32: Medido del modelo / factor en Supuestos
A33: 03 Estructura de concreto | B33: Estadio | C33: 03.05 | D33: Gradas: cimbra | E33: m² | F33: =($F$29+$F$30+$F$31)*Supuestos!$C$43 -> 129136.84 | G33: 620 | H33: =F33*G33 -> 80064840 | I33: Cimbra | J33: Medido del modelo / factor en Supuestos
A34: 03 Estructura de concreto | B34: Estadio | C34: 03.06 | D34: Losas de vestíbulos L0, L0.5, L1 y L2 (postensadas) | E34: m³ | F34: =(Cantidades_Modelo!$C$12+Cantidades_Modelo!$C$13+Cantidades_Modelo!$C$14+Cantidades_Modelo!$C$15)*Supuestos!$C$23 -> 56024.834 | G34: 3550 | H34: =F34*G34 -> 1.9888816e+08 | I34: Concreto f'c 400 | J34: Medido del modelo / factor en Supuestos
A35: 03 Estructura de concreto | B35: Estadio | C35: 03.07 | D35: Losas de vestíbulos: acero de refuerzo | E35: kg | F35: =$F$34*Supuestos!$C$36 -> 6162731.7 | G35: 31 | H35: =F35*G35 -> 1.9104468e+08 | I35: Varilla corrugada fy 4200 | J35: Medido del modelo / factor en Supuestos
A36: 03 Estructura de concreto | B36: Estadio | C36: 03.08 | D36: Losas de vestíbulos: torón de postensado | E36: kg | F36: =(Cantidades_Modelo!$C$12+Cantidades_Modelo!$C$13+Cantidades_Modelo!$C$14+Cantidades_Modelo!$C$15)*Supuestos!$C$39 -> 1120496.7 | G36: 78 | H36: =F36*G36 -> 87398740 | I36: Torón 0.6" y anclajes | J36: Medido del modelo / factor en Supuestos
A37: 03 Estructura de concreto | B37: Estadio | C37: 03.09 | D37: Losas de vestíbulos: cimbra | E37: m² | F37: =$F$34*Supuestos!$C$40 -> 168074.5 | G37: 520 | H37: =F37*G37 -> 87398740 | I37: Cimbra | J37: Medido del modelo / factor en Supuestos
A38: 03 Estructura de concreto | B38: Estadio | C38: 03.10 | D38: Columnas del estadio f'c 500 (Ø 1.2–1.4 m) | E38: m³ | F38: =Cantidades_Modelo!$C$53 -> 7367.82 | G38: 4200 | H38: =F38*G38 -> 30944844 | I38: Concreto f'c 500 | J38: Medido del modelo / factor en Supuestos
A39: 03 Estructura de concreto | B39: Estadio | C39: 03.11 | D39: Columnas del estadio: acero de refuerzo | E39: kg | F39: =$F$38*Supuestos!$C$37 -> 1620920.4 | G39: 31 | H39: =F39*G39 -> 50248532 | I39: Varilla corrugada fy 4200 | J39: Medido del modelo / factor en Supuestos
A40: 03 Estructura de concreto | B40: Estadio | C40: 03.12 | D40: Columnas del estadio: cimbra metálica circular | E40: m² | F40: =$F$38*Supuestos!$C$42 -> 36839.1 | G40: 780 | H40: =F40*G40 -> 28734498 | I40: Cimbra | J40: Medido del modelo / factor en Supuestos
A41: 03 Estructura de concreto | B41: Estadio | C41: 03.13 | D41: Núcleos de escape (16) y núcleos de elevadores de torres (8) | E41: m³ | F41: =16*Supuestos!$C$30+8*Supuestos!$C$31 -> 10552 | G41: 3800 | H41: =F41*G41 -> 40097600 | I41: Concreto f'c 400 | J41: Medido del modelo / factor en Supuestos
...

Sheet Materiales
A1: Lista de materiales e insumos (suma de todas las partidas)
A3: Material / insumo | B3: Unidad | C3: Cantidad | D3: Importe (MXN) | E3: Partidas
A4: Acabados de lujo | B4: m² | C4: =SUMIFS(Presupuesto!$F$5:$F$231,Presupuesto!$I$5:$I$231,$A4,Presupuesto!$E$5:$E$231,$B4) -> 4773.168 | D4: =SUMIFS(Presupuesto!$H$5:$H$231,Presupuesto!$I$5:$I$231,$A4,Presupuesto!$E$5:$E$231,$B4) -> 124102368 | E4: =COUNTIFS(Presupuesto!$I$5:$I$231,$A4,Presupuesto!$E$5:$E$231,$B4) -> 1
A5: Acabados y equipo | B5: pza | C5: =SUMIFS(Presupuesto!$F$5:$F$231,Presupuesto!$I$5:$I$231,$A5,Presupuesto!$E$5:$E$231,$B5) -> 24 | D5: =SUMIFS(Presupuesto!$H$5:$H$231,Presupuesto!$I$5:$I$231,$A5,Presupuesto!$E$5:$E$231,$B5) -> 62400000 | E5: =COUNTIFS(Presupuesto!$I$5:$I$231,$A5,Presupuesto!$E$5:$E$231,$B5) -> 1
A6: Acabados y equipo deportivo | B6: m² | C6: =SUMIFS(Presupuesto!$F$5:$F$231,Presupuesto!$I$5:$I$231,$A6,Presupuesto!$E$5:$E$231,$B6) -> 4600 | D6: =SUMIFS(Presupuesto!$H$5:$H$231,Presupuesto!$I$5:$I$231,$A6,Presupuesto!$E$5:$E$231,$B6) -> 193200000 | E6: =COUNTIFS(Presupuesto!$I$5:$I$231,$A6,Presupuesto!$E$5:$E$231,$B6) -> 1
A7: Acarreo en camión | B7: m³ | C7: =SUMIFS(Presupuesto!$F$5:$F$231,Presupuesto!$I$5:$I$231,$A7,Presupuesto!$E$5:$E$231,$B7) -> 3714385.2 | D7: =SUMIFS(Presupuesto!$H$5:$H$231,Presupuesto!$I$5:$I$231,$A7,Presupuesto!$E$5:$E$231,$B7) -> 5.3858585e+08 | E7: =COUNTIFS(Presupuesto!$I$5:$I$231,$A7,Presupuesto!$E$5:$E$231,$B7) -> 1
A8: Acero estructural A572 | B8: kg | C8: =SUMIFS(Presupuesto!$F$5:$F$231,Presupuesto!$I$5:$I$231,$A8,Presupuesto!$E$5:$E$231,$B8) -> 12755788 | D8: =SUMIFS(Presupuesto!$H$5:$H$231,Presupuesto!$I$5:$I$231,$A8,Presupuesto!$E$5:$E$231,$B8) -> 1.4789688e+09 | E8: =COUNTIFS(Presupuesto!$I$5:$I$231,$A8,Presupuesto!$E$5:$E$231,$B8) -> 11
A9: Acero estructural A572 / cables | B9: kg | C9: =SUMIFS(Presupuesto!$F$5:$F$231,Presupuesto!$I$5:$I$231,$A9,Presupuesto!$E$5:$E$231,$B9) -> 8103833.5 | D9: =SUMIFS(Presupuesto!$H$5:$H$231,Presupuesto!$I$5:$I$231,$A9,Presupuesto!$E$5:$E$231,$B9) -> 9.5625235e+08 | E9: =COUNTIFS(Presupuesto!$I$5:$I$231,$A9,Presupuesto!$E$5:$E$231,$B9) -> 1
A10: Acero inoxidable / línea de vida | B10: m | C10: =SUMIFS(Presupuesto!$F$5:$F$231,Presupuesto!$I$5:$I$231,$A10,Presupuesto!$E$5:$E$231,$B10) -> 1591.056 | D10: =SUMIFS(Presupuesto!$H$5:$H$231,Presupuesto!$I$5:$I$231,$A10,Presupuesto!$E$5:$E$231,$B10) -> 15115032 | E10: =COUNTIFS(Presupuesto!$I$5:$I$231,$A10,Presupuesto!$E$5:$E$231,$B10) -> 1
A11: Aditivo para concreto | B11: L | C11: =SUMIFS(Presupuesto!$F$5:$F$231,Presupuesto!$I$5:$I$231,$A11,Presupuesto!$E$5:$E$231,$B11) -> 2785127.6 | D11: =SUMIFS(Presupuesto!$H$5:$H$231,Presupuesto!$I$5:$I$231,$A11,Presupuesto!$E$5:$E$231,$B11) -> 1.7267791e+08 | E11: =COUNTIFS(Presupuesto!$I$5:$I$231,$A11,Presupuesto!$E$5:$E$231,$B11) -> 1
A12: Aislador de base elastomérico | B12: pza | C12: =SUMIFS(Presupuesto!$F$5:$F$231,Presupuesto!$I$5:$I$231,$A12,Presupuesto!$E$5:$E$231,$B12) -> 420 | D12: =SUMIFS(Presupuesto!$H$5:$H$231,Presupuesto!$I$5:$I$231,$A12,Presupuesto!$E$5:$E$231,$B12) -> 399000000 | E12: =COUNTIFS(Presupuesto!$I$5:$I$231,$A12,Presupuesto!$E$5:$E$231,$B12) -> 1
A13: Alambre recocido | B13: kg | C13: =SUMIFS(Presupuesto!$F$5:$F$231,Presupuesto!$I$5:$I$231,$A13,Presupuesto!$E$5:$E$231,$B13) -> 1188885.4 | D13: =SUMIFS(Presupuesto!$H$5:$H$231,Presupuesto!$I$5:$I$231,$A13,Presupuesto!$E$5:$E$231,$B13) -> 45177645 | E13: =COUNTIFS(Presupuesto!$I$5:$I$231,$A13,Presupuesto!$E$5:$E$231,$B13) -> 1
A14: Ancla química | B14: pza | C14: =SUMIFS(Presupuesto!$F$5:$F$231,Presupuesto!$I$5:$I$231,$A14,Presupuesto!$E$5:$E$231,$B14) -> 248220 | D14: =SUMIFS(Presupuesto!$H$5:$H$231,Presupuesto!$I$5:$I$231,$A14,Presupuesto!$E$5:$E$231,$B14) -> 39715200 | E14: =COUNTIFS(Presupuesto!$I$5:$I$231,$A14,Presupuesto!$E$5:$E$231,$B14) -> 1
A15: Asiento abatible + señalización | B15: pza | C15: =SUMIFS(Presupuesto!$F$5:$F$231,Presupuesto!$I$5:$I$231,$A15,Presupuesto!$E$5:$E$231,$B15) -> 1021 | D15: =SUMIFS(Presupuesto!$H$5:$H$231,Presupuesto!$I$5:$I$231,$A15,Presupuesto!$E$5:$E$231,$B15) -> 9699500 | E15: =COUNTIFS(Presupuesto!$I$5:$I$231,$A15,Presupuesto!$E$5:$E$231,$B15) -> 1
... A155: Árbol nativo | B155: pza | C155: =SUMIFS(Presupuesto!$F$5:$F$231,Presupuesto!$I$5:$I$231,$A155,Presupuesto!$E$5:$E$231,$B155) -> 1261 | D155: =SUMIFS(Presupuesto!$H$5:$H$231,Presupuesto!$I$5:$I$231,$A155,Presupuesto!$E$5:$E$231,$B155) -> 35308000 | E155: =COUNTIFS(Presupuesto!$I$5:$I$231,$A155,Presupuesto!$E$5:$E$231,$B155) -> 1
A156: TOTAL | D156: =SUM(D4:D155) -> 3.7234597e+10

Sheet Supuestos
A1: Supuestos y factores (celdas azules = editables)
A3: Clave | B3: Supuesto | C3: Valor | D3: Unidad | E3: Nota
A4: tc | B4: Tipo de cambio | C4: 18.5 | D4: MXN/USD | E4: Supuesto editable; actualízalo al día de la cotización
A5: pct_ind | B5: Indirectos de obra (campo y oficina) | C5: 0.12 | D5: % | E5: Típico 10–15 % en obra mayor
A6: pct_util | B6: Utilidad del contratista | C6: 0.08 | D6: % | E6: Típico 6–10 %
A7: pct_proy | B7: Proyecto ejecutivo e ingenierías | C7: 0.06 | D7: % | E7: Arquitectura, estructura, MEP, especialidades
A8: pct_lic | B8: Licencias, permisos, DRO y corresponsables | C8: 0.015 | D8: %
A9: pct_sup | B9: Supervisión y gerencia de proyecto | C9: 0.025 | D9: %
A10: pct_cont | B10: Contingencia | C10: 0.1 | D10: % | E10: Por ser estimado de concepto (±25 %)
A11: iva | B11: IVA | C11: 0.16 | D11: %
A12: meses | B12: Duración de obra | C12: 48 | D12: meses
A13: abund | B13: Abundamiento de material excavado | C13: 1.25 | D13: factor
A14: prof_exc | B14: Profundidad de excavación (12 m + 1 m de cimentación) | C14: 13 | D14: m
A15: prof_muro | B15: Profundidad del muro Milán | C15: 18 | D15: m
A16: e_muro | B16: Espesor del muro Milán | C16: 0.8 | D16: m
A17: e_cim | B17: Espesor de losa de cimentación | C17: 0.9 | D17: m
A18: n_pilas | B18: Pilas de cimentación Ø1.2 m | C18: 1291 | D18: pza | E18: 2 por columna del estadio, 1 por columna de la plaza, 4 por núcleo
A19: L_pila | B19: Longitud de pila | C19: 25 | D19: m | E19: Depende del estudio de mecánica de suelos
A20: e_grada1 | B20: Espesor de losa de grada 1 (sobre relleno) | C20: 0.25 | D20: m
A21: e_grada23 | B21: Espesor equivalente gradas 2 y 3 (prefabricados + trabes) | C21: 0.55 | D21: m
A22: f_incl | B22: Factor de inclinación de gradas | C22: 1.15 | D22: factor
A23: e_vest | B23: Espesor equivalente losas de vestíbulos | C23: 0.45 | D23: m | E23: Losa postensada con capiteles
A24: e_P1 | B24: Espesor equivalente losa P1 | C24: 0.35 | D24: m
A25: e_plaza | B25: Espesor losa de plaza (carga de jardín y bomberos) | C25: 0.6 | D25: m
A26: e_sakbe | B26: Espesor equivalente entrepisos Plaza Sakbé | C26: 0.3 | D26: m | E26: Losa postensada
A27: e_azotea | B27: Espesor losa de azotea verde | C27: 0.45 | D27: m
A28: col_estac_m3 | B28: Volumen por columna de estacionamiento (0.6×0.6×12 m) | C28: 4.32 | D28: m³/pza
A29: col_sakbe_m3 | B29: Volumen por columna de la plaza (0.8×0.8×57 m) | C29: 36.48 | D29: m³/pza
A30: nuc_est_m3 | B30: Concreto por núcleo de escape del estadio | C30: 542 | D30: m³/pza | E30: 42 m perímetro × 43 m × 0.30 m
A31: nuc_torre_m3 | B31: Concreto por núcleo de elevadores en torre | C31: 235 | D31: m³/pza
A32: nuc_sakbe_m3 | B32: Concreto por núcleo de la plaza | C32: 650 | D32: m³/pza | E32: 38 m perímetro × 57 m × 0.30 m
A33: k_cim | B33: Acero de refuerzo en cimentación | C33: 95 | D33: kg/m³
A34: k_muro | B34: Acero de refuerzo en muros | C34: 120 | D34: kg/m³
A35: k_pila | B35: Acero de refuerzo en pilas | C35: 85 | D35: kg/m³
A36: k_losa | B36: Acero de refuerzo en losas | C36: 110 | D36: kg/m³
A37: k_col | B37: Acero de refuerzo en columnas | C37: 220 | D37: kg/m³
A38: k_grada | B38: Acero de refuerzo en gradas | C38: 150 | D38: kg/m³
A39: k_post | B39: Torón de postensado | C39: 9 | D39: kg/m² de losa
A40: c_losa | B40: Cimbra en losas | C40: 3 | D40: m²/m³
A41: c_muro | B41: Cimbra en muros y núcleos | C41: 6.7 | D41: m²/m³
...

Sheet Cantidades_Modelo
A1: Cantidades medidas en el modelo de Blender (estadio_yaxche.py)
A3: Clave | B3: Descripción | C3: Cantidad | D3: Unidad | E3: Fuente
A4: sitio_m2 | B4: Superficie total del predio (estadio + plaza + explanada) | C4: 283535.79 | D4: m² | E4: Medido del modelo 3D v3 (geometría / conteo)
A5: huella_sub_m2 | B5: Huella subterránea (dentro del muro perimetral) | C5: 228577.55 | D5: m² | E5: Medido del modelo 3D v3 (geometría / conteo)
A6: perim_muro | B6: Perímetro del muro Milán | C6: 1706.53 | D6: m | E6: Medido del modelo 3D v3 (geometría / conteo)
A7: perim_sitio | B7: Perímetro del predio | C7: 1900.26 | D7: m | E7: Medido del modelo 3D v3 (geometría / conteo)
A8: t1_plan | B8: Grada 1: área en planta | C8: 16737.03 | D8: m² | E8: Medido del modelo 3D v3 (geometría / conteo)
A9: t2_plan | B9: Grada 2: área en planta | C9: 19733.01 | D9: m² | E9: Medido del modelo 3D v3 (geometría / conteo)
A10: t3_plan | B10: Grada 3: área en planta | C10: 27944.18 | D10: m² | E10: Medido del modelo 3D v3 (geometría / conteo)
A11: grada_sup | B11: Superficie escalonada de gradas (huellas + peraltes + pasillos) | C11: 100157.61 | D11: m² | E11: Medido del modelo 3D v3 (geometría / conteo)
A12: L0 | B12: Vestíbulo L0 (planta) | C12: 48428.54 | D12: m² | E12: Medido del modelo 3D v3 (geometría / conteo)
A13: L05 | B13: Mezzanine L0.5 (planta) | C13: 27044.61 | D13: m² | E13: Medido del modelo 3D v3 (geometría / conteo)
A14: L1 | B14: Vestíbulo L1 (planta) | C14: 27871.13 | D14: m² | E14: Medido del modelo 3D v3 (geometría / conteo)
A15: L2 | B15: Vestíbulo L2 (planta) | C15: 21155.35 | D15: m² | E15: Medido del modelo 3D v3 (geometría / conteo)
... A83: arena_temp | B83: Butacas de gradas telescópicas (modo arena) | C83: 3384 | D83: pza | E83: Medido del modelo 3D v3 (geometría / conteo)

Sheet Medidas
A1: Medidas generales (largo × ancho)
A3: Elemento | B3: Largo (m) | C3: Ancho (m) | D3: Área (m²)
A4: Cancha | B4: 105 | C4: 68 | D4: =B4*C4 -> 7140
A5: Zona de campo | B5: 125 | C5: 84 | D5: =B5*C5 -> 10500
A6: Estadio (fachada) | B6: 322 | C6: 281 | D6: =B6*C6 -> 90482
A7: Estadio con cubierta | B7: 361 | C7: 320 | D7: =B7*C7 -> 115520
A8: Plaza Sakbé (borde exterior) | B8: 537 | C8: 496 | D8: =B8*C8 -> 266352
A9: Todo con explanada | B9: 597 | C9: 556 | D9: =B9*C9 -> 331932
A11: Área real del predio (forma superelíptica) | D11: =Cantidades_Modelo!$C$4 -> 283535.79
A12: Nota: largo × ancho es el rectángulo que lo contiene; el área real es menor porque las esquinas son redondeadas.
